Workbook
Name Hoy: TODAY()
Name Incremento_de_desplazamiento: GANTT_SFCO211!$C$7
Name Inicio_del_proyecto: GANTT_SFCO211!$C$6

Sheet GRAFICO
B1: sem1 | C1: sem2 | D1: sem3 | E1: sem4 | F1: sem5 | G1: sem6 | H1: sem7 | I1: sem8 | J1: sem9 | K1: sem10 | L1: sem11 | M1: sem12 | N1: sem13 | O1: sem14 | P1: sem15 | Q1: sem16 | R1: sem17 | S1: sem18 | T1: sem19 | U1: sem20 | V1: sem21 | W1: sem22 | X1: sem23 | Y1: sem24 | Z1: sem25 | AA1: sem26 | AB1: sem27
A2: Trazado | G2: {=TRANSPOSE(D43:V43)} -> 0.62078232 | H2: {=TRANSPOSE(D42:V42)} -> 0.67184234 | I2: {=TRANSPOSE(D41:V41)} -> 0.74440131 | J2: {=TRANSPOSE(D40:V40)} -> 0.79008659 | K2: {=TRANSPOSE(D39:V39)} -> 0.84393937 | L2: {=TRANSPOSE(D38:V38)} -> 0.89245253 | M2: {=TRANSPOSE(D37:V37)} -> 0.94087787 | N2: {=TRANSPOSE(D36:V36)} -> 0.95700209 | O2: {=TRANSPOSE(D35:V35)} -> 0.95700209 | P2: {=TRANSPOSE(D34:V34)} -> 1 | Q2: {=TRANSPOSE(D33:V33)} -> 1 | R2: {=TRANSPOSE(D32:V32)} -> 1 | S2: {=TRANSPOSE(D31:V31)} -> 1 | T2: {=TRANSPOSE(D30:V30)} -> 1 | U2: {=TRANSPOSE(D29:V29)} -> 1 | V2: {=TRANSPOSE(D28:V28)} -> 1 | W2: {=TRANSPOSE(D27:V27)} -> 1 | X2: {=TRANSPOSE(D26:V26)} -> 1 | Y2: 1 | Z2: 1 | AA2: 1 | AB2: 1
A3: Yeso Cielo | G3: 0.81964766 | H3: 0.81964766 | I3: 0.91400418 | J3: 0.91400418 | K3: 0.91400418 | L3: 0.91400418 | M3: 0.91400418 | N3: 1 | O3: 1 | P3: 1 | Q3: 1 | R3: 1 | S3: 1 | T3: 1 | U3: 1 | V3: 1 | W3: 1 | X3: 1 | Y3: {=TRANSPOSE(E25:W25)} -> 1 | Z3: 1 | AA3: 1 | AB3: 1
A4: Yeso Muro | G4: 0.67506718 | H4: 0.73096447 | I4: 0.77503732 | J4: 0.85255651 | K4: 0.9198356 | L4: 0.97957599 | M4: 1 | N4: 1 | O4: 1 | P4: 1 | Q4: 1 | R4: 1 | S4: 1 | T4: 1 | U4: 1 | V4: 1 | W4: 1 | X4: 1 | Y4: 1 | Z4: 1 | AA4: 1 | AB4: 1
A5: Tabique 1° Cara | G5: 0.58584652 | H5: 0.6438937 | I5: 0.72558973 | J5: 0.73096447 | K5: 0.80997313 | L5: 0.81696029 | M5: 0.92206629 | N5: 0.94195282 | O5: 0.97312631 | P5: 1 | Q5: 1 | R5: 1 | S5: 1 | T5: 1 | U5: 1 | V5: 1 | W5: 1 | X5: 1 | Y5: 1 | Z5: 1 | AA5: 1 | AB5: 1
A6: I. Sanitaria | G6: 0.69871603 | H6: 0.75515079 | I6: 0.75515079 | J6: 0.82240528 | K6: 0.81970913 | L6: 0.8681696 | M6: 0.8681696 | N6: 0.8681696 | O6: 0.89778336 | P6: 0.96288444 | Q6: 0.97363392 | R6: 0.97470887 | S6: 0.98708658 | T6: 0.99140042 | U6: 0.99140042 | V6: 0.99140042 | W6: 0.99516274 | X6: 1 | Y6: 1 | Z6: 1 | AA6: 1 | AB6: 1
A7: I. Eléctrica | G7: 0.50630039 | H7: 0.52994924 | I7: 0.56918483 | J7: 0.59337116 | K7: 0.63260675 | L7: 0.66754255 | M7: 0.70677814 | N7: 0.72182741 | O7: 0.81430805 | P7: 0.89408427 | Q7: 0.93224492 | R7: 0.96828904 | S7: 0.98333831 | T7: 0.99086294 | U7: 0.99140042 | V7: 0.99140042 | W7: 0.99140042 | X7: 0.99838758 | Y7: 1 | Z7: 1 | AA7: 1 | AB7: 1
A8: Extracción | G8: 0.54446103 | H8: 0.586384 | I8: 0.62561959 | J8: 0.66754255 | K8: 0.68527919 | L8: 0.68742908 | M8: 0.73795163 | N8: 0.74305763 | O8: 0.74305763 | P8: 0.83938665 | Q8: 0.86332531 | R8: 0.91231096 | S8: 0.94947746 | T8: 0.97850105 | U8: 0.99570021 | V8: 0.99570021 | W8: 1 | X8: 1 | Y8: 1 | Z8: 1 | AA8: 1 | AB8: 1
A9: Tabique 2° Cara | G9: 0.45685279 | H9: 0.52188713 | I9: 0.5471484 | J9: 0.54822335 | K9: 0.6336817 | L9: 0.6336817 | M9: 0.63959391 | N9: 0.69925351 | O9: 0.8083607 | P9: 0.90052342 | Q9: 0.91346495 | R9: 0.91400418 | S9: 0.99892505 | T9: 0.99946253 | U9: 1 | V9: 1 | W9: 1 | X9: 1 | Y9: 1 | Z9: 1 | AA9: 1 | AB9: 1
A10: Puertas | G10: 0.26443715 | H10: 0.2951269 | I10: 0.35303971 | J10: 0.43057032 | K10: 0.47055838 | L10: 0.54365482 | M10: 0.58880263 | N10: 0.64322186 | O10: 0.67856076 | P10: 0.75246342 | Q10: 0.80878445 | R10: 0.83585662 | S10: 0.87016274 | T10: 0.87703792 | U10: 0.92433562 | V10: 0.92433562 | W10: 0.952553 | X10: 0.95443416 | Y10: 0.95443416 | Z10: 0.95443416 | AA10: 0.95443416 | AB10: 0.95443416
A11: Cerámicos | G11: 0.25026575 | H11: 0.29989251 | I11: 0.33509704 | J11: 0.36161242 | K11: 0.36996118 | L11: 0.4265751 | M11: 0.48202448 | N11: 0.53684682 | O11: 0.56067483 | P11: 0.64935802 | Q11: 0.66843834 | R11: 0.70597193 | S11: 0.7231711 | T11: 0.7839156 | U11: 0.79001692 | V11: 0.81976446 | W11: 0.86691784 | X11: 0.88147208 | Y11: 0.89365482 | Z11: 0.91157062 | AA11: 0.939788 | AB11: 0.9393401
A12: Piso Vinilico | G12: 0.13073229 | H12: 0.16206483 | I12: 0.23013205 | J12: 0.29387755 | K12: 0.31008403 | L12: 0.31818727 | M12: 0.36734694 | N12: 0.45918367 | O12: 0.43487395 | P12: 0.48781513 | Q12: 0.54129652 | R12: 0.55102041 | S12: 0.58883553 | T12: 0.6494898 | U12: 0.6933413 | V12: 0.6933413 | W12: 0.6933413 | X12: 0.83150194 | Y12: 0.88191998 | Z12: 0.88191998 | AA12: 0.91963273 | AB12: 0.97499254
A13: Ventanas | G13: 0.31522843 | H13: 0.43857868 | I13: 0.43857868 | J13: 0.43857868 | K13: 0.53451777 | L13: 0.61218274 | M13: 0.60304569 | N13: 0.5893401 | O13: 0.63051657 | P13: 0.70316512 | Q13: 0.75583756 | R13: 0.80158256 | S13: 0.81528815 | T13: 0.87011048 | U13: 0.90504628 | V13: 0.93063601 | W13: 0.93923559 | X13: 0.95241863 | Y13: 0.95241863 | Z13: 0.95241863 | AA13: 0.95241863 | AB13: 0.95241863
A14: Baranda Cristal | G14: 0.026873694 | H14: 0.026873694 | I14: 0.026873694 | J14: 0.026873694 | K14: 0.026873694 | L14: 0.026873694 | M14: 0.026873694 | N14: 0.026873694 | O14: 0.026873694 | P14: 0.026873694 | Q14: 0.026873694 | R14: 0.026873694 | S14: 0.026873694 | T14: 0.04998507 | U14: 0.04998507 | V14: 0.080621081 | W14: 0.16071171 | X14: 0.22762721 | Y14: 0.37167021 | Z14: 0.59230323 | AA14: 0.68559271 | AB14: 0.92093162
A15: Pasta | G15: 0.44368468 | H15: 0.46357122 | I15: 0.60761421 | J15: 0.72654524 | K15: 0.81343685 | L15: 0.81343685 | M15: 0.8225739 | N15: 0.83171096 | O15: 0.83171096 | P15: 0.82553001 | Q15: 0.82714243 | R15: 0.83009854 | S15: 0.83009854 | T15: 0.83171096 | U15: 0.83171096 | V15: 0.84541654 | W15: 0.86825918 | X15: 0.86825918 | Y15: 0.86825918 | Z15: 0.86825918 | AA15: 0.86825918 | AB15: 0.92845626
... A20: Retropintado | G20: 0.012899373 | H20: 0.012899373 | I20: 0.012899373 | J20: 0.012899373 | K20: 0.012899373 | L20: 0.049447596 | M20: 0.056434757 | N20: 0.23917587 | O20: 0.26766199 | P20: 0.24025082 | Q20: 0.27303673 | R20: 0.24938788 | S20: 0.32355927 | T20: 0.32355927 | U20: 0.35553897 | V20: 0.42863541 | W20: 0.43320394 | X20: 0.43320394 | Y20: 0.47888922 | Z20: 0.61137653 | AA20: 0.61137653 | AB20: 0.62965064
Y21: 0
C22: 27 | D22: 1 | E22: 1 | F22: 1 | G22: 1 | H22: 1 | I22: 1 | J22: 1 | K22: 1 | L22: 0.95443416 | M22: 0.9393401 | N22: 0.97499254 | O22: 0.95241863 | P22: 0.92093162 | Q22: 0.92845626 | R22: 0.62886024 | S22: 0.86173953 | T22: 0.74923858 | U22: 1 | V22: 0.62965064
C23: 26 | D23: 1 | E23: 1 | F23: 1 | G23: 1 | H23: 1 | I23: 1 | J23: 1 | K23: 1 | L23: 0.95443416 | M23: 0.939788 | N23: 0.91963273 | O23: 0.95241863 | P23: 0.68559271 | Q23: 0.86825918 | R23: 0.60869663 | S23: 0.82062307 | T23: 0.72182741 | U23: 0.82233503 | V23: 0.61137653
C24: 25 | D24: 1 | E24: 1 | F24: 1 | G24: 1 | H24: 1 | I24: 1 | J24: 1 | K24: 1 | L24: 0.95443416 | M24: 0.91157062 | N24: 0.88191998 | O24: 0.95241863 | P24: 0.59230323 | Q24: 0.86825918 | R24: 0.60574052 | S24: 0.78541853 | T24: 0.67614213 | U24: 0.82233503 | V24: 0.61137653
C25: 24 | D25: 1 | E25: 1 | F25: 1 | G25: 1 | H25: 1 | I25: 1 | J25: 1 | K25: 1 | L25: 0.95443416 | M25: 0.89365482 | N25: 0.88191998 | O25: 0.95241863 | P25: 0.37167021 | Q25: 0.86825918 | R25: 0.60574052 | S25: 0.75684284 | T25: 0.65141833 | U25: 0.73096447 | V25: 0.47888922
C26: 23 | D26: 1 | E26: 1 | F26: 1 | G26: 1 | H26: 1 | I26: 0.99838758 | J26: 1 | K26: 1 | L26: 0.95443416 | M26: 0.88147208 | N26: 0.83150194 | O26: 0.95241863 | P26: 0.22762721 | Q26: 0.86825918 | R26: 0.60352344 | S26: 0.65661391 | T26: 0.55171693 | U26: 0.73096447 | V26: 0.43320394
C27: 22 | D27: 1 | E27: 1 | F27: 1 | G27: 1 | H27: 0.99516274 | I27: 0.99140042 | J27: 1 | K27: 1 | L27: 0.952553 | M27: 0.86691784 | N27: 0.6933413 | O27: 0.93923559 | P27: 0.16071171 | Q27: 0.86825918 | R27: 0.59835025 | S27: 0.62400717 | T27: 0.54311735 | U27: 0.64873096 | V27: 0.43320394
A28: Valores | C28: 21 | D28: 1 | E28: 1 | F28: 1 | G28: 1 | H28: 0.99140042 | I28: 0.99140042 | J28: 0.99570021 | K28: 1 | L28: 0.92433562 | M28: 0.81976446 | N28: 0.6933413 | O28: 0.93063601 | P28: 0.080621081 | Q28: 0.84541654 | R28: 0.5633398 | S28: 0.61289937 | T28: 0.50764407 | U28: 0.63959391 | V28: 0.42863541
A29: Promedio de Trazado | B29: #REF! | C29: 20 | D29: 1 | E29: 1 | F29: 1 | G29: 1 | H29: 0.99140042 | I29: 0.99140042 | J29: 0.99570021 | K29: 1 | L29: 0.92433562 | M29: 0.79001692 | N29: 0.6933413 | O29: 0.90504628 | P29: 0.04998507 | Q29: 0.83171096 | R29: 0.54372201 | S29: 0.58181547 | T29: 0.45228426 | U29: 0.57563452 | V29: 0.35553897
A30: Suma de Yeso Cielo | B30: #REF! | C30: 19 | D30: 1 | E30: 1 | F30: 1 | G30: 1 | H30: 0.99140042 | I30: 0.99086294 | J30: 0.97850105 | K30: 0.99946253 | L30: 0.87703792 | M30: 0.7839156 | N30: 0.6494898 | O30: 0.87011048 | P30: 0.04998507 | Q30: 0.83171096 | R30: 0.51268289 | S30: 0.56192893 | T30: 0.43320394 | U30: 0.54822335 | V30: 0.32355927
A31: Suma de Yeso Muro | B31: #REF! | C31: 18 | D31: 1 | E31: 1 | F31: 1 | G31: 1 | H31: 0.98708658 | I31: 0.98333831 | J31: 0.94947746 | K31: 0.99892505 | L31: 0.87016274 | M31: 0.7231711 | N31: 0.58883553 | O31: 0.81528815 | P31: 0.026873694 | Q31: 0.83009854 | R31: 0.42137952 | S31: 0.49080322 | T31: 0.37085697 | U31: 0.45685279 | V31: 0.32355927
A32: Suma de Tabique 1° Cara | B32: #REF! | C32: 17 | D32: 1 | E32: 1 | F32: 1 | G32: 1 | H32: 0.97470887 | I32: 0.96828904 | J32: 0.91231096 | K32: 0.91400418 | L32: 0.83585662 | M32: 0.70597193 | N32: 0.55102041 | O32: 0.80158256 | P32: 0.026873694 | Q32: 0.83009854 | R32: 0.39584951 | S32: 0.46930427 | T32: 0.34720812 | U32: 0.45685279 | V32: 0.24938788
A33: Suma de I. Sanitaria | B33: #REF! | C33: 16 | D33: 1 | E33: 1 | F33: 1 | G33: 1 | H33: 0.97363392 | I33: 0.93224492 | J33: 0.86332531 | K33: 0.91346495 | L33: 0.80878445 | M33: 0.66843834 | N33: 0.54129652 | O33: 0.75583756 | P33: 0.026873694 | Q33: 0.82714243 | R33: 0.35822634 | S33: 0.43660794 | T33: 0.34720812 | U33: 0.45577784 | V33: 0.27303673
A34: Suma de I. Eléctrica | B34: #REF! | C34: 15 | D34: 1 | E34: 1 | F34: 1 | G34: 1 | H34: 0.96288444 | I34: 0.89408427 | J34: 0.83938665 | K34: 0.90052342 | L34: 0.75246342 | M34: 0.64935802 | N34: 0.48781513 | O34: 0.70316512 | P34: 0.026873694 | Q34: 0.82553001 | R34: 0.35822634 | S34: 0.41725888 | T34: 0.34720812 | U34: 0.43857868 | V34: 0.24025082
A35: Suma de Extracción | B35: #REF! | C35: 14 | D35: 0.95700209 | E35: 1 | F35: 1 | G35: 0.97312631 | H35: 0.89778336 | I35: 0.81430805 | J35: 0.74305763 | K35: 0.8083607 | L35: 0.67856076 | M35: 0.56067483 | N35: 0.43487395 | O35: 0.63051657 | P35: 0.026873694 | Q35: 0.83171096 | R35: 0.32664975 | S35: 0.33744401 | T35: 0.28217378 | U35: 0.36091371 | V35: 0.26766199
A36: Suma de Tabique 2° Cara | B36: #REF! | C36: 13 | D36: 0.95700209 | E36: 1 | F36: 1 | G36: 0.94195282 | H36: 0.8681696 | I36: 0.72182741 | J36: 0.74305763 | K36: 0.69925351 | L36: 0.64322186 | M36: 0.53684682 | N36: 0.45918367 | O36: 0.5893401 | P36: 0.026873694 | Q36: 0.83171096 | R36: 0.3183189 | S36: 0.32741117 | T36: 0.25959988 | U36: 0.36091371 | V36: 0.23917587 | W36: 0.60653158
A37: Suma de Puertas | B37: #REF! | C37: 12 | D37: 0.94087787 | E37: 0.91400418 | F37: 1 | G37: 0.92206629 | H37: 0.8681696 | I37: 0.70677814 | J37: 0.73795163 | K37: 0.63959391 | L37: 0.58880263 | M37: 0.48202448 | N37: 0.36734694 | O37: 0.60304569 | P37: 0.026873694 | Q37: 0.8225739 | R37: 0.3055539 | S37: 0.30304569 | T37: 0.18650343 | U37: 0.27411168 | V37: 0.056434757
A38: Suma de Cerámicos | B38: #REF! | C38: 11 | D38: 0.89245253 | E38: 0.91400418 | F38: 0.97957599 | G38: 0.81696029 | H38: 0.8681696 | I38: 0.66754255 | J38: 0.68742908 | K38: 0.6336817 | L38: 0.54365482 | M38: 0.4265751 | N38: 0.31818727 | O38: 0.61218274 | P38: 0.026873694 | Q38: 0.81343685 | R38: 0.29386384 | S38: 0.27411168 | T38: 0.16822932 | U38: 0.27411168 | V38: 0.049447596
A39: Suma de Piso Vinilico | B39: #REF! | C39: 10 | D39: 0.84393937 | E39: 0.91400418 | F39: 0.9198356 | G39: 0.80997313 | H39: 0.81970913 | I39: 0.63260675 | J39: 0.68527919 | K39: 0.6336817 | L39: 0.47055838 | M39: 0.36996118 | N39: 0.31008403 | O39: 0.53451777 | P39: 0.026873694 | Q39: 0.81343685 | R39: 0.26537772 | S39: 0.24105703 | T39: 0.12093162 | U39: 0.27411168 | V39: 0.012899373
A40: Suma de Ventanas | B40: #REF! | C40: 9 | D40: 0.79008659 | E40: 0.91400418 | F40: 0.85255651 | G40: 0.73096447 | H40: 0.82240528 | I40: 0.59337116 | J40: 0.66754255 | K40: 0.54822335 | L40: 0.43057032 | M40: 0.36161242 | N40: 0.29387755 | O40: 0.43857868 | P40: 0.026873694 | Q40: 0.72654524 | R40: 0.26403404 | S40: 0.21928934 | T40: 0.10158256 | U40: 0.21015228 | V40: 0.012899373
A41: Suma de Baranda Cristal | B41: #REF! | C41: 8 | D41: 0.74440131 | E41: 0.91400418 | F41: 0.77503732 | G41: 0.72558973 | H41: 0.75515079 | I41: 0.56918483 | J41: 0.62561959 | K41: 0.5471484 | L41: 0.35303971 | M41: 0.33509704 | N41: 0.23013205 | O41: 0.43857868 | P41: 0.026873694 | Q41: 0.60761421 | R41: 0.19409525 | S41: 0.15837563 | T41: 0.062346969 | U41: 0.091370558 | V41: 0.012899373
A42: Suma de Pasta | B42: #REF! | C42: 7 | D42: 0.67184234 | E42: 0.81964766 | F42: 0.73096447 | G42: 0.6438937 | H42: 0.75515079 | I42: 0.52994924 | J42: 0.586384 | K42: 0.52188713 | L42: 0.2951269 | M42: 0.29989251 | N42: 0.16206483 | O42: 0.43857868 | P42: 0.026873694 | Q42: 0.46357122 | R42: 0.15203792 | S42: 0.13266647 | T42: 0.020424007 | U42: 0.021498955 | V42: 0.012899373
A43: Suma de Muebles C/B | B43: #REF! | C43: 6 | D43: 0.62078232 | E43: 0.81964766 | F43: 0.67506718 | G43: 0.58584652 | H43: 0.69871603 | I43: 0.50630039 | J43: 0.54446103 | K43: 0.45685279 | L43: 0.26443715 | M43: 0.25026575 | N43: 0.13073229 | O43: 0.31522843 | P43: 0.026873694 | Q43: 0.44368468 | R43: 0.138937 | S43: 0.079725291 | T43: 0.020424007 | U43: 0.021498955 | V43: 0.012899373
A44: Suma de Muebles Closet | B44: #REF! | C44: 5
...

Sheet DINAMICA
A4: Etiquetas de fila | B4: Máx. de PISO 1 | C4: Máx. de PISO 2 | D4: Máx. de PISO 3 | E4: Máx. de PISO 4 | F4: Máx. de PISO 5 | G4: Máx. de PISO 6 | H4: Máx. de PISO 7 | I4: Máx. de PISO 8 | J4: Máx. de PISO 9
A5: FASE 1 | B5: 0.240625 | C5: 0.11697674 | D5: 0.0090909091 | E5: 0 | F5: 0 | G5: 0 | H5: 0 | I5: 0 | J5: 0
A6: Total general | B6: 0.240625 | C6: 0.11697674 | D6: 0.0090909091 | E6: 0 | F6: 0 | G6: 0 | H6: 0 | I6: 0 | J6: 0
A9: Etiquetas de fila | B9: Máx. de PISO 1 | C9: Máx. de PISO 2 | D9: Máx. de PISO 3 | E9: Máx. de PISO 4 | F9: Máx. de PISO 5 | G9: Máx. de PISO 6 | H9: Máx. de PISO 7 | I9: Máx. de PISO 8 | J9: Máx. de PISO 9
A10: FASE 2 | B10: 0 | C10: 0 | D10: 0 | E10: 0 | F10: 0 | G10: 0 | H10: 0 | I10: 0 | J10: 0
A11: Total general | B11: 0 | C11: 0 | D11: 0 | E11: 0 | F11: 0 | G11: 0 | H11: 0 | I11: 0 | J11: 0
A13: Etiquetas de fila | B13: Máx. de PISO 1 | C13: Máx. de PISO 2 | D13: Máx. de PISO 3 | E13: Máx. de PISO 4 | F13: Máx. de PISO 5 | G13: Máx. de PISO 6 | H13: Máx. de PISO 7 | I13: Máx. de PISO 8 | J13: Máx. de PISO 9
A14: FASE 3 | B14: 0 | C14: 0 | D14: 0 | E14: 0 | F14: 0 | G14: 0 | H14: 0 | I14: 0 | J14: 0
A15: Total general | B15: 0 | C15: 0 | D15: 0 | E15: 0 | F15: 0 | G15: 0 | H15: 0 | I15: 0 | J15: 0
A17: Etiquetas de fila | B17: Máx. de PISO 1 | C17: Máx. de PISO 2 | D17: Máx. de PISO 3 | E17: Máx. de PISO 4 | F17: Máx. de PISO 5 | G17: Máx. de PISO 6 | H17: Máx. de PISO 7 | I17: Máx. de PISO 8 | J17: Máx. de PISO 9
A18: FASE 4 | B18: 0 | C18: 0 | D18: 0 | E18: 0 | F18: 0 | G18: 0 | H18: 0 | I18: 0 | J18: 0
A19: Total general | B19: 0 | C19: 0 | D19: 0 | E19: 0 | F19: 0 | G19: 0 | H19: 0 | I19: 0 | J19: 0
A22: Etiquetas de fila | B22: Máx. de PISO 1 | C22: Máx. de PISO 2 | D22: Máx. de PISO 3 | E22: Máx. de PISO 4 | F22: Máx. de PISO 5 | G22: Máx. de PISO 6 | H22: Máx. de PISO 7 | I22: Máx. de PISO 8 | J22: Máx. de PISO 9
A23: FASE 4 | B23: 0 | C23: 0 | D23: 0 | E23: 0 | F23: 0 | G23: 0 | H23: 0 | I23: 0 | J23: 0
A24: Total general | B24: 0 | C24: 0 | D24: 0 | E24: 0 | F24: 0 | G24: 0 | H24: 0 | I24: 0 | J24: 0
A47: Máx. de PISO 1 | B47: Máx. de PISO 2 | C47: Máx. de PISO 3 | D47: Máx. de PISO 4 | E47: Máx. de PISO 5 | F47: Máx. de PISO 6 | G47: Máx. de PISO 7 | H47: Máx. de PISO 8 | I47: Máx. de PISO 9
A48: 0.06015625 | B48: 0.029244186 | C48: 0.0022727273 | D48: 0 | E48: 0 | F48: 0 | G48: 0 | H48: 0 | I48: 0

Sheet FASE 4
O1: Avance General
C2: CONTROL AVANCE FASE 4 SAN FRANCISCO 211
M3: Cantidad de Deptos. | N3: 359 | O3: =+AVERAGE(C33,C79,C126,C173,C220,C267,C314,C361,C405) -> 0
C5: 1 | D5: 2 | E5: 3 | F5: 4 | G5: 5 | H5: 6 | I5: 7 | J5: 8 | K5: 9 | L5: 10 | M5: 11 | N5: 12
B6: Deptos. | C6: Instalacion de Artefactos Sanitarios. | D6: Extractor de baño. | E6: Instalación de Shower Door | F6: Instalacion de Espejos y Retropintados | G6: Kit de cocina (Horno-Encimera -Campana - Lavaplato) | H6: Griferia. | I6: Pruebas de Instalaciones. | J6: Piso Flotante + cubrejunta + junquillo | K6: Protección Piso Flotante | L6: 2da Mano de Pintura | M6: Instalación de Papel Mural | N6: Topes en piso y Accesorios | O6: Avance Real x Piso
A7: PISO N° 1 | B7: DEPTO 102 | C7: 0 | D7: 0 | E7: 0 | F7: 0 | G7: 0 | H7: 0 | I7: 0 | J7: 0 | K7: 0 | L7: 0 | M7: 0 | N7: 0 | O7: =+AVERAGE(C7:N7) -> 0
B8: DEPTO 103 | C8: 0 | D8: 0 | E8: 0 | F8: 0 | G8: 0 | H8: 0 | I8: 0 | J8: 0 | K8: 0 | L8: 0 | M8: 0 | N8: 0 | O8: =+AVERAGE(C8:N8) -> 0
B9: DEPTO 104 | C9: 0 | D9: 0 | E9: 0 | F9: 0 | G9: 0 | H9: 0 | I9: 0 | J9: 0 | K9: 0 | L9: 0 | M9: 0 | N9: 0 | O9: =+AVERAGE(C9:N9) -> 0
B10: DEPTO 105 | C10: 0 | D10: 0 | E10: 0 | F10: 0 | G10: 0 | H10: 0 | I10: 0 | J10: 0 | K10: 0 | L10: 0 | M10: 0 | N10: 0 | O10: =+AVERAGE(C10:N10) -> 0
B11: DEPTO 106 | C11: 0 | D11: 0 | E11: 0 | F11: 0 | G11: 0 | H11: 0 | I11: 0 | J11: 0 | K11: 0 | L11: 0 | M11: 0 | N11: 0 | O11: =+AVERAGE(C11:N11) -> 0
B12: DEPTO 107 | C12: 0 | D12: 0 | E12: 0 | F12: 0 | G12: 0 | H12: 0 | I12: 0 | J12: 0 | K12: 0 | L12: 0 | M12: 0 | N12: 0 | O12: =+AVERAGE(C12:N12) -> 0
B13: DEPTO 108 | C13: 0 | D13: 0 | E13: 0 | F13: 0 | G13: 0 | H13: 0 | I13: 0 | J13: 0 | K13: 0 | L13: 0 | M13: 0 | N13: 0 | O13: =+AVERAGE(C13:N13) -> 0
B14: DEPTO 118 | C14: 0 | D14: 0 | E14: 0 | F14: 0 | G14: 0 | H14: 0 | I14: 0 | J14: 0 | K14: 0 | L14: 0 | M14: 0 | N14: 0 | O14: =+AVERAGE(C14:N14) -> 0
B15: DEPTO 119 | C15: 0 | D15: 0 | E15: 0 | F15: 0 | G15: 0 | H15: 0 | I15: 0 | J15: 0 | K15: 0 | L15: 0 | M15: 0 | N15: 0 | O15: =+AVERAGE(C15:N15) -> 0
B16: DEPTO 120 | C16: 0 | D16: 0 | E16: 0 | F16: 0 | G16: 0 | H16: 0 | I16: 0 | J16: 0 | K16: 0 | L16: 0 | M16: 0 | N16: 0 | O16: =+AVERAGE(C16:N16) -> 0
B17: DEPTO 121 | C17: 0 | D17: 0 | E17: 0 | F17: 0 | G17: 0 | H17: 0 | I17: 0 | J17: 0 | K17: 0 | L17: 0 | M17: 0 | N17: 0 | O17: =+AVERAGE(C17:N17) -> 0
B18: LOCAL 1 | C18: 0 | D18: 0 | E18: 0 | F18: 0 | G18: 0 | H18: 0 | I18: 0 | J18: 0 | K18: 0 | L18: 0 | M18: 0 | N18: 0 | O18: =+AVERAGE(C18:N18) -> 0
B19: LOCAL 2 | C19: 0 | D19: 0 | E19: 0 | F19: 0 | G19: 0 | H19: 0 | I19: 0 | J19: 0 | K19: 0 | L19: 0 | M19: 0 | N19: 0 | O19: =+AVERAGE(C19:N19) -> 0
... B30: SALON GOURMET 2 | C30: 0 | D30: 0 | E30: 0 | F30: 0 | G30: 0 | H30: 0 | I30: 0 | J30: 0 | K30: 0 | L30: 0 | M30: 0 | N30: 0 | O30: =+AVERAGE(C30:N30) -> 0
A31: GRAFICO DE AVANCE POR PARTIDA
A32: PORCENTAJE POR PARTIDA | C32: =+AVERAGE(C7:C30) -> 0 | D32: =+AVERAGE(D7:D30) -> 0 | E32: =+AVERAGE(E7:E30) -> 0 | F32: =+AVERAGE(F7:F30) -> 0 | G32: =+AVERAGE(G7:G30) -> 0 | H32: =+AVERAGE(H7:H30) -> 0 | I32: =+AVERAGE(I7:I30) -> 0 | J32: =+AVERAGE(J7:J30) -> 0 | ... N32: =+AVERAGE(N7:N30) -> 0
A33: AVANCE GENERAL PISO N° 1 | C33: =+AVERAGE(C32:N32) -> 0
A34: PISO N° 2 A | B34: Depto 202 | C34: 0 | D34: 0 | E34: 0 | F34: 0 | G34: 0 | H34: 0 | I34: 0 | J34: 0 | K34: 0 | L34: 0 | M34: 0 | N34: 0 | O34: =+AVERAGE(C34:N34) -> 0
B35: Depto.203 | C35: 0 | D35: 0 | E35: 0 | F35: 0 | G35: 0 | H35: 0 | I35: 0 | J35: 0 | K35: 0 | L35: 0 | M35: 0 | N35: 0 | O35: =+AVERAGE(C35:N35) -> 0
B36: Depto.204 | C36: 0 | D36: 0 | E36: 0 | F36: 0 | G36: 0 | H36: 0 | I36: 0 | J36: 0 | K36: 0 | L36: 0 | M36: 0 | N36: 0 | O36: =+AVERAGE(C36:N36) -> 0
B37: Depto.205 | C37: 0 | D37: 0 | E37: 0 | F37: 0 | G37: 0 | H37: 0 | I37: 0 | J37: 0 | K37: 0 | L37: 0 | M37: 0 | N37: 0 | O37: =+AVERAGE(C37:N37) -> 0
B38: Depto.206 | C38: 0 | D38: 0 | E38: 0 | F38: 0 | G38: 0 | H38: 0 | I38: 0 | J38: 0 | K38: 0 | L38: 0 | M38: 0 | N38: 0 | O38: =+AVERAGE(C38:N38) -> 0
B39: Depto.207 | C39: 0 | D39: 0 | E39: 0 | F39: 0 | G39: 0 | H39: 0 | I39: 0 | J39: 0 | K39: 0 | L39: 0 | M39: 0 | N39: 0 | O39: =+AVERAGE(C39:N39) -> 0
B40: Depto.208 | C40: 0 | D40: 0 | E40: 0 | F40: 0 | G40: 0 | H40: 0 | I40: 0 | J40: 0 | K40: 0 | L40: 0 | M40: 0 | N40: 0 | O40: =+AVERAGE(C40:N40) -> 0
B41: Depto.209 | C41: 0 | D41: 0 | E41: 0 | F41: 0 | G41: 0 | H41: 0 | I41: 0 | J41: 0 | K41: 0 | L41: 0 | M41: 0 | N41: 0 | O41: =+AVERAGE(C41:N41) -> 0
B42: Depto.210 | C42: 0 | D42: 0 | E42: 0 | F42: 0 | G42: 0 | H42: 0 | I42: 0 | J42: 0 | K42: 0 | L42: 0 | M42: 0 | N42: 0 | O42: =+AVERAGE(C42:N42) -> 0
B43: Depto.211 | C43: 0 | D43: 0 | E43: 0 | F43: 0 | G43: 0 | H43: 0 | I43: 0 | J43: 0 | K43: 0 | L43: 0 | M43: 0 | N43: 0 | O43: =+AVERAGE(C43:N43) -> 0
B44: Depto.212 | C44: 0 | D44: 0 | E44: 0 | F44: 0 | G44: 0 | H44: 0 | I44: 0 | J44: 0 | K44: 0 | L44: 0 | M44: 0 | N44: 0 | O44: =+AVERAGE(C44:N44) -> 0
B45: Depto.213 | C45: 0 | D45: 0 | E45: 0 | F45: 0 | G45: 0 | H45: 0 | I45: 0 | J45: 0 | K45: 0 | L45: 0 | M45: 0 | N45: 0 | O45: =+AVERAGE(C45:N45) -> 0
B46: Depto.214 | C46: 0 | D46: 0 | E46: 0 | F46: 0 | G46: 0 | H46: 0 | I46: 0 | J46: 0 | K46: 0 | L46: 0 | M46: 0 | N46: 0 | O46: =+AVERAGE(C46:N46) -> 0
... B55: Depto.223 | C55: 0 | D55: 0 | E55: 0 | F55: 0 | G55: 0 | H55: 0 | I55: 0 | J55: 0 | K55: 0 | L55: 0 | M55: 0 | N55: 0 | O55: =+AVERAGE(C55:N55) -> 0
A56: PISO N° 2 B | B56: Depto.201 | C56: 0 | D56: 0 | E56: 0 | F56: 0 | G56: 0 | H56: 0 | I56: 0 | J56: 0 | K56: 0 | L56: 0 | M56: 0 | N56: 0 | O56: =+AVERAGE(C56:N56) -> 0
B57: Depto.202 | C57: 0 | D57: 0 | E57: 0 | F57: 0 | G57: 0 | H57: 0 | I57: 0 | J57: 0 | K57: 0 | L57: 0 | M57: 0 | N57: 0 | O57: =+AVERAGE(C57:N57) -> 0
B58: Depto.203 | C58: 0 | D58: 0 | E58: 0 | F58: 0 | G58: 0 | H58: 0 | I58: 0 | J58: 0 | K58: 0 | L58: 0 | M58: 0 | N58: 0 | O58: =+AVERAGE(C58:N58) -> 0
B59: Depto.204 | C59: 0 | D59: 0 | E59: 0 | F59: 0 | G59: 0 | H59: 0 | I59: 0 | J59: 0 | K59: 0 | L59: 0 | M59: 0 | N59: 0 | O59: =+AVERAGE(C59:N59) -> 0
...

Sheet FASE 3 
X1: Avance General
C2: CONTROL AVANCE FASE 3 SAN FRANCISCO 211
V3: Cantidad de Deptos. | W3: 359 | X3: =+AVERAGE(C33,C79,C126,C173,C220,C267,C314,C361,C405) -> 0.0088183422
C5: 1 | D5: 2 | E5: 3 | F5: 4 | G5: 5 | H5: 6 | I5: 7 | J5: 8 | K5: 9 | L5: 10 | M5: 11 | N5: 12 | O5: 13 | P5: 14 | Q5: 15 | R5: 16 | S5: 17 | T5: 18 | U5: 19 | V5: 20 | W5: 21
B6: Deptos. | C6: Instalación piernas de closet | D6: Instalación Cornisas | E6: Cuadratura de cajas. | F6: Remate yeso y cornisas | G6: Puertas interiores | H6: Puertas de acceso y pasillo | I6: Cerradura Puertas | J6: Cableado Eléctrico y CCDD | K6: Canterias | L6: Empaste Muro Cielo | M6: Instalacion Guardapolvo | N6: Instalación de Baranda de Crital | O6: Pintura Cielo Terrazas | P6: Grano Muros Terrazas | Q6: Losalin Cielo Departamento | R6: Pintura Cielo Baños | S6: Instalacion de Muebles baño | T6: Instalacion Muebles de cocina (Base) | U6: Instalacion Muebles de cocina (Aereo) | V6: Instalación cubiertas cocina | W6: Muebles Interior closet | X6: Avance Real x Piso
A7: PISO N° 1 | B7: DEPTO 102 | C7: 0 | D7: 0 | E7: 0 | F7: 0 | G7: 0 | H7: 0 | I7: 0 | J7: 0 | K7: 0 | L7: 0 | M7: 0 | N7: 0 | O7: 0 | P7: 0 | Q7: 0 | R7: 0 | S7: 0 | T7: 0 | U7: 0 | V7: 0 | W7: 0 | X7: =+AVERAGE(C7:W7) -> 0
B8: DEPTO 103 | C8: 0 | D8: 0 | E8: 1 | F8: 0 | G8: 0 | H8: 0 | I8: 0 | J8: 0 | K8: 0 | L8: 0 | M8: 0 | N8: 0 | O8: 0 | P8: 0 | Q8: 0 | R8: 0 | S8: 0 | T8: 0 | U8: 0 | V8: 0 | W8: 0 | X8: =+AVERAGE(C8:W8) -> 0.047619048
B9: DEPTO 104 | C9: 0 | D9: 0 | E9: 1 | F9: 0 | G9: 0 | H9: 0 | I9: 0 | J9: 0 | K9: 0 | L9: 0 | M9: 0 | N9: 0 | O9: 0 | P9: 0 | Q9: 0 | R9: 0 | S9: 0 | T9: 0 | U9: 0 | V9: 0 | W9: 0 | X9: =+AVERAGE(C9:W9) -> 0.047619048
B10: DEPTO 105 | C10: 0 | D10: 0 | E10: 1 | F10: 0 | G10: 0 | H10: 0 | I10: 0 | J10: 0 | K10: 0 | L10: 0 | M10: 0 | N10: 0 | O10: 0 | P10: 0 | Q10: 0 | R10: 0 | S10: 0 | T10: 0 | U10: 0 | V10: 0 | W10: 0 | X10: =+AVERAGE(C10:W10) -> 0.047619048
B11: DEPTO 106 | C11: 0 | D11: 0 | E11: 1 | F11: 0 | G11: 0 | H11: 0 | I11: 0 | J11: 0 | K11: 0 | L11: 0 | M11: 0 | N11: 0 | O11: 0 | P11: 0 | Q11: 0 | R11: 0 | S11: 0 | T11: 0 | U11: 0 | V11: 0 | W11: 0 | X11: =+AVERAGE(C11:W11) -> 0.047619048
B12: DEPTO 107 | C12: 0 | D12: 0 | E12: 1 | F12: 0 | G12: 0 | H12: 0 | I12: 0 | J12: 0 | K12: 0 | L12: 0 | M12: 0 | N12: 0 | O12: 0 | P12: 0 | Q12: 0 | R12: 0 | S12: 0 | T12: 0 | U12: 0 | V12: 0 | W12: 0 | X12: =+AVERAGE(C12:W12) -> 0.047619048
B13: DEPTO 108 | C13: 0 | D13: 0 | E13: 1 | F13: 0 | G13: 0 | H13: 0 | I13: 0 | J13: 0 | K13: 0 | L13: 0 | M13: 0 | N13: 0 | O13: 0 | P13: 0 | Q13: 0 | R13: 0 | S13: 0 | T13: 0 | U13: 0 | V13: 0 | W13: 0 | X13: =+AVERAGE(C13:W13) -> 0.047619048
B14: DEPTO 118 | C14: 0 | D14: 0 | E14: 0 | F14: 0 | G14: 0 | H14: 0 | I14: 0 | J14: 0 | K14: 0 | L14: 0 | M14: 0 | N14: 0 | O14: 0 | P14: 0 | Q14: 0 | R14: 0 | S14: 0 | T14: 0 | U14: 0 | V14: 0 | W14: 0 | X14: =+AVERAGE(C14:W14) -> 0
B15: DEPTO 119 | C15: 0 | D15: 0 | E15: 0 | F15: 0 | G15: 0 | H15: 0 | I15: 0 | J15: 0 | K15: 0 | L15: 0 | M15: 0 | N15: 0 | O15: 0 | P15: 0 | Q15: 0 | R15: 0 | S15: 0 | T15: 0 | U15: 0 | V15: 0 | W15: 0 | X15: =+AVERAGE(C15:W15) -> 0
B16: DEPTO 120 | C16: 0 | D16: 1 | E16: 1 | F16: 1 | G16: 1 | H16: 0 | I16: 1 | J16: 1 | K16: 0 | L16: 1 | M16: 1 | N16: 1 | O16: 1 | P16: 1 | Q16: 1 | R16: 1 | S16: 1 | T16: 1 | U16: 1 | V16: 1 | W16: 0 | X16: =+AVERAGE(C16:W16) -> 0.80952381
B17: DEPTO 121 | C17: 0 | D17: 1 | E17: 1 | F17: 1 | G17: 1 | H17: 0 | I17: 1 | J17: 1 | K17: 0 | L17: 1 | M17: 1 | N17: 1 | O17: 1 | P17: 1 | Q17: 1 | R17: 1 | S17: 1 | T17: 1 | U17: 1 | V17: 1 | W17: 0 | X17: =+AVERAGE(C17:W17) -> 0.80952381
B18: LOCAL 1 | C18: 0 | D18: 0 | E18: 0 | F18: 0 | G18: 0 | H18: 0 | I18: 0 | J18: 0 | K18: 0 | L18: 0 | M18: 0 | N18: 0 | O18: 0 | P18: 0 | Q18: 0 | R18: 0 | S18: 0 | T18: 0 | U18: 0 | V18: 0 | W18: 0 | X18: =+AVERAGE(C18:W18) -> 0
B19: LOCAL 2 | C19: 0 | D19: 0 | E19: 0 | F19: 0 | G19: 0 | H19: 0 | I19: 0 | J19: 0 | K19: 0 | L19: 0 | M19: 0 | N19: 0 | O19: 0 | P19: 0 | Q19: 0 | R19: 0 | S19: 0 | T19: 0 | U19: 0 | V19: 0 | W19: 0 | X19: =+AVERAGE(C19:W19) -> 0
... B30: SALON GOURMET 2 | C30: 0 | D30: 0 | E30: 0 | F30: 0 | G30: 0 | H30: 0 | I30: 0 | J30: 0 | K30: 0 | L30: 0 | M30: 0 | N30: 0 | O30: 0 | P30: 0 | Q30: 0 | R30: 0 | S30: 0 | T30: 0 | U30: 0 | V30: 0 | W30: 0 | X30: =+AVERAGE(C30:W30) -> 0
A31: GRAFICO DE AVANCE POR PARTIDA
A32: PORCENTAJE POR PARTIDA | C32: =+AVERAGE(C7:C30) -> 0 | D32: =+AVERAGE(D7:D30) -> 0.083333333 | E32: =+AVERAGE(E7:E30) -> 0.33333333 | F32: =+AVERAGE(F7:F30) -> 0.083333333 | G32: =+AVERAGE(G7:G30) -> 0.083333333 | H32: =+AVERAGE(H7:H30) -> 0 | I32: =+AVERAGE(I7:I30) -> 0.083333333 | J32: =+AVERAGE(J7:J30) -> 0.083333333 | ... W32: =+AVERAGE(W7:W30) -> 0
A33: AVANCE GENERAL PISO N° 1 | C33: =+AVERAGE(C32:W32) -> 0.079365079
A34: PISO N° 2 A | B34: Depto 202 | C34: 0 | D34: 0 | E34: 0 | F34: 0 | G34: 0 | H34: 0 | I34: 0 | J34: 0 | K34: 0 | L34: 0 | M34: 0 | N34: 0 | O34: 0 | P34: 0 | Q34: 0 | R34: 0 | S34: 0 | T34: 0 | U34: 0 | V34: 0 | W34: 0 | X34: =+AVERAGE(C34:W34) -> 0
B35: Depto.203 | C35: 0 | D35: 0 | E35: 0 | F35: 0 | G35: 0 | H35: 0 | I35: 0 | J35: 0 | K35: 0 | L35: 0 | M35: 0 | N35: 0 | O35: 0 | P35: 0 | Q35: 0 | R35: 0 | S35: 0 | T35: 0 | U35: 0 | V35: 0 | W35: 0 | X35: =+AVERAGE(C35:W35) -> 0
B36: Depto.204 | C36: 0 | D36: 0 | E36: 0 | F36: 0 | G36: 0 | H36: 0 | I36: 0 | J36: 0 | K36: 0 | L36: 0 | M36: 0 | N36: 0 | O36: 0 | P36: 0 | Q36: 0 | R36: 0 | S36: 0 | T36: 0 | U36: 0 | V36: 0 | W36: 0 | X36: =+AVERAGE(C36:W36) -> 0
B37: Depto.205 | C37: 0 | D37: 0 | E37: 0 | F37: 0 | G37: 0 | H37: 0 | I37: 0 | J37: 0 | K37: 0 | L37: 0 | M37: 0 | N37: 0 | O37: 0 | P37: 0 | Q37: 0 | R37: 0 | S37: 0 | T37: 0 | U37: 0 | V37: 0 | W37: 0 | X37: =+AVERAGE(C37:W37) -> 0
B38: Depto.206 | C38: 0 | D38: 0 | E38: 0 | F38: 0 | G38: 0 | H38: 0 | I38: 0 | J38: 0 | K38: 0 | L38: 0 | M38: 0 | N38: 0 | O38: 0 | P38: 0 | Q38: 0 | R38: 0 | S38: 0 | T38: 0 | U38: 0 | V38: 0 | W38: 0 | X38: =+AVERAGE(C38:W38) -> 0
B39: Depto.207 | C39: 0 | D39: 0 | E39: 0 | F39: 0 | G39: 0 | H39: 0 | I39: 0 | J39: 0 | K39: 0 | L39: 0 | M39: 0 | N39: 0 | O39: 0 | P39: 0 | Q39: 0 | R39: 0 | S39: 0 | T39: 0 | U39: 0 | V39: 0 | W39: 0 | X39: =+AVERAGE(C39:W39) -> 0
B40: Depto.208 | C40: 0 | D40: 0 | E40: 0 | F40: 0 | G40: 0 | H40: 0 | I40: 0 | J40: 0 | K40: 0 | L40: 0 | M40: 0 | N40: 0 | O40: 0 | P40: 0 | Q40: 0 | R40: 0 | S40: 0 | T40: 0 | U40: 0 | V40: 0 | W40: 0 | X40: =+AVERAGE(C40:W40) -> 0
B41: Depto.209 | C41: 0 | D41: 0 | E41: 0 | F41: 0 | G41: 0 | H41: 0 | I41: 0 | J41: 0 | K41: 0 | L41: 0 | M41: 0 | N41: 0 | O41: 0 | P41: 0 | Q41: 0 | R41: 0 | S41: 0 | T41: 0 | U41: 0 | V41: 0 | W41: 0 | X41: =+AVERAGE(C41:W41) -> 0
B42: Depto.210 | C42: 0 | D42: 0 | E42: 0 | F42: 0 | G42: 0 | H42: 0 | I42: 0 | J42: 0 | K42: 0 | L42: 0 | M42: 0 | N42: 0 | O42: 0 | P42: 0 | Q42: 0 | R42: 0 | S42: 0 | T42: 0 | U42: 0 | V42: 0 | W42: 0 | X42: =+AVERAGE(C42:W42) -> 0
B43: Depto.211 | C43: 0 | D43: 0 | E43: 0 | F43: 0 | G43: 0 | H43: 0 | I43: 0 | J43: 0 | K43: 0 | L43: 0 | M43: 0 | N43: 0 | O43: 0 | P43: 0 | Q43: 0 | R43: 0 | S43: 0 | T43: 0 | U43: 0 | V43: 0 | W43: 0 | X43: =+AVERAGE(C43:W43) -> 0
B44: Depto.212 | C44: 0 | D44: 0 | E44: 0 | F44: 0 | G44: 0 | H44: 0 | I44: 0 | J44: 0 | K44: 0 | L44: 0 | M44: 0 | N44: 0 | O44: 0 | P44: 0 | Q44: 0 | R44: 0 | S44: 0 | T44: 0 | U44: 0 | V44: 0 | W44: 0 | X44: =+AVERAGE(C44:W44) -> 0
B45: Depto.213 | C45: 0 | D45: 0 | E45: 0 | F45: 0 | G45: 0 | H45: 0 | I45: 0 | J45: 0 | K45: 0 | L45: 0 | M45: 0 | N45: 0 | O45: 0 | P45: 0 | Q45: 0 | R45: 0 | S45: 0 | T45: 0 | U45: 0 | V45: 0 | W45: 0 | X45: =+AVERAGE(C45:W45) -> 0
B46: Depto.214 | C46: 0 | D46: 0 | E46: 0 | F46: 0 | G46: 0 | H46: 0 | I46: 0 | J46: 0 | K46: 0 | L46: 0 | M46: 0 | N46: 0 | O46: 0 | P46: 0 | Q46: 0 | R46: 0 | S46: 0 | T46: 0 | U46: 0 | V46: 0 | W46: 0 | X46: =+AVERAGE(C46:W46) -> 0
... B55: Depto.223 | C55: 0 | D55: 0 | E55: 0 | F55: 0 | G55: 0 | H55: 0 | I55: 0 | J55: 0 | K55: 0 | L55: 0 | M55: 0 | N55: 0 | O55: 0 | P55: 0 | Q55: 0 | R55: 0 | S55: 0 | T55: 0 | U55: 0 | V55: 0 | W55: 0 | X55: =+AVERAGE(C55:W55) -> 0
A56: PISO N° 2 B | B56: Depto.201 | C56: 0 | D56: 0 | E56: 0 | F56: 0 | G56: 0 | H56: 0 | I56: 0 | J56: 0 | K56: 0 | L56: 0 | M56: 0 | N56: 0 | O56: 0 | P56: 0 | Q56: 0 | R56: 0 | S56: 0 | T56: 0 | U56: 0 | V56: 0 | W56: 0 | X56: =+AVERAGE(C56:W56) -> 0
B57: Depto.202 | C57: 0 | D57: 0 | E57: 0 | F57: 0 | G57: 0 | H57: 0 | I57: 0 | J57: 0 | K57: 0 | L57: 0 | M57: 0 | N57: 0 | O57: 0 | P57: 0 | Q57: 0 | R57: 0 | S57: 0 | T57: 0 | U57: 0 | V57: 0 | W57: 0 | X57: =+AVERAGE(C57:W57) -> 0
B58: Depto.203 | C58: 0 | D58: 0 | E58: 0 | F58: 0 | G58: 0 | H58: 0 | I58: 0 | J58: 0 | K58: 0 | L58: 0 | M58: 0 | N58: 0 | O58: 0 | P58: 0 | Q58: 0 | R58: 0 | S58: 0 | T58: 0 | U58: 0 | V58: 0 | W58: 0 | X58: =+AVERAGE(C58:W58) -> 0
B59: Depto.204 | C59: 0 | D59: 0 | E59: 0 | F59: 0 | G59: 0 | H59: 0 | I59: 0 | J59: 0 | K59: 0 | L59: 0 | M59: 0 | N59: 0 | O59: 0 | P59: 0 | Q59: 0 | R59: 0 | S59: 0 | T59: 0 | U59: 0 | V59: 0 | W59: 0 | X59: =+AVERAGE(C59:W59) -> 0
...

Sheet FASE 2  
R1: Avance General
C2: CONTROL AVANCE FASE 2 SAN FRANCISCO 211
P3: Cantidad de Deptos. | Q3: 359 | R3: =+AVERAGE(C33,C79,C126,C173,C220,C267,C314,C361,C405) -> 0.013179012
C5: 1 | D5: 2 | E5: 3 | F5: 4 | G5: 5 | H5: 6 | I5: 7 | J5: 8 | K5: 9 | L5: 10 | M5: 11 | N5: 12 | O5: 13 | P5: 14 | Q5: 15
B6: Deptos. | C6: Huinchas tabiques | D6: Instalación Marco Puerta Acceso | E6: Marcos Puertas Interiores | F6: Impermeabilizacion Baños | G6: Impermeabilizacion Terrazas | H6: Preparación de Pisos | I6: Instalacion de tina/Receptaculo | J6: Protección Tina/receptaculo | K6: Faldon de tina. | L6: Instalación Ventana | M6: Ceramica Pisos | N6: Ceramica Muros | O6: Instalación de Gargolas en Terraza | P6: Frague | Q6: Cerámica de Terrazas | R6: Avance Real x Piso
A7: PISO N° 1 | B7: DEPTO 102 | C7: 0 | D7: 0 | E7: 0 | F7: 0.8 | G7: 0 | H7: 0.9 | I7: 0 | J7: 0 | K7: 0 | L7: 0 | M7: 0 | N7: 0 | O7: 0 | P7: 0 | Q7: 0 | R7: =+AVERAGE(P7:Q7,C7:N7) -> 0.12142857
B8: DEPTO 103 | C8: 0 | D8: 0 | E8: 0 | F8: 0.8 | G8: 1 | H8: 0.9 | I8: 0 | J8: 0 | K8: 0 | L8: 0 | M8: 0 | N8: 0 | O8: 0 | P8: 0 | Q8: 1 | R8: =+AVERAGE(P8:Q8,C8:N8) -> 0.26428571
B9: DEPTO 104 | C9: 0 | D9: 0 | E9: 0 | F9: 0.8 | G9: 1 | H9: 0.9 | I9: 0 | J9: 0 | K9: 0 | L9: 0 | M9: 0 | N9: 0 | O9: 0 | P9: 0 | Q9: 1 | R9: =+AVERAGE(P9:Q9,C9:N9) -> 0.26428571
B10: DEPTO 105 | C10: 0 | D10: 0 | E10: 0 | F10: 0.8 | G10: 0 | H10: 0.9 | I10: 0 | J10: 0 | K10: 0 | L10: 0 | M10: 0 | N10: 0 | O10: 0 | P10: 0 | Q10: 0 | R10: =+AVERAGE(P10:Q10,C10:N10) -> 0.12142857
B11: DEPTO 106 | C11: 0 | D11: 0 | E11: 0 | F11: 0.8 | G11: 0 | H11: 0.9 | I11: 0 | J11: 0 | K11: 0 | L11: 0 | M11: 0 | N11: 0 | O11: 0 | P11: 0 | Q11: 0 | R11: =+AVERAGE(P11:Q11,C11:N11) -> 0.12142857
B12: DEPTO 107 | C12: 0 | D12: 0 | E12: 0 | F12: 0.8 | G12: 0 | H12: 0.9 | I12: 0 | J12: 0 | K12: 0 | L12: 0 | M12: 0 | N12: 0 | O12: 0 | P12: 0 | Q12: 0 | R12: =+AVERAGE(P12:Q12,C12:N12) -> 0.12142857
B13: DEPTO 108 | C13: 0 | D13: 0 | E13: 0 | F13: 0 | G13: 0 | H13: 0.9 | I13: 0 | J13: 0 | K13: 0 | L13: 0 | M13: 0 | N13: 0 | O13: 0 | P13: 0 | Q13: 0 | R13: =+AVERAGE(P13:Q13,C13:N13) -> 0.064285714
B14: DEPTO 118 | C14: 0 | D14: 0 | E14: 0 | F14: 0 | G14: 0 | H14: 0 | I14: 0 | J14: 0 | K14: 0 | L14: 0 | M14: 0 | N14: 0 | O14: 0 | P14: 0 | Q14: 0 | R14: =+AVERAGE(P14:Q14,C14:N14) -> 0
B15: DEPTO 119 | C15: 0 | D15: 0 | E15: 0 | F15: 0 | G15: 0 | H15: 0 | I15: 0 | J15: 0 | K15: 0 | L15: 0 | M15: 0 | N15: 0 | O15: 0 | P15: 0 | Q15: 0 | R15: =+AVERAGE(P15:Q15,C15:N15) -> 0
B16: DEPTO 120 | C16: 1 | D16: 1 | E16: 1 | F16: 1 | G16: 1 | H16: 1 | I16: 1 | J16: 1 | K16: 1 | L16: 1 | M16: 0 | N16: 0 | O16: 0 | P16: 0 | Q16: 1 | R16: =+AVERAGE(P16:Q16,C16:N16) -> 0.78571429
B17: DEPTO 121 | C17: 1 | D17: 1 | E17: 1 | F17: 1 | G17: 1 | H17: 1 | I17: 1 | J17: 1 | K17: 1 | L17: 1 | M17: 1 | N17: 1 | O17: 0 | P17: 1 | Q17: 0 | R17: =+AVERAGE(P17:Q17,C17:N17) -> 0.92857143
B18: LOCAL 1 | C18: 0 | D18: 0 | E18: 0 | F18: 0 | G18: 0 | H18: 0 | I18: 0 | J18: 0 | K18: 0 | L18: 0 | M18: 0 | N18: 0 | O18: 0 | P18: 0 | Q18: 0 | R18: =+AVERAGE(P18:Q18,C18:N18) -> 0
B19: LOCAL 2 | C19: 0 | D19: 0 | E19: 0 | F19: 0 | G19: 0 | H19: 0 | I19: 0 | J19: 0 | K19: 0 | L19: 0 | M19: 0 | N19: 0 | O19: 0 | P19: 0 | Q19: 0 | R19: =+AVERAGE(P19:Q19,C19:N19) -> 0
... B30: SALON GOURMET 2 | C30: 0 | D30: 0 | E30: 0 | F30: 0 | G30: 0 | H30: 0 | I30: 0 | J30: 0 | K30: 0 | L30: 0 | M30: 0 | N30: 0 | O30: 0 | P30: 0 | Q30: 0 | R30: =+AVERAGE(P30:Q30,C30:N30) -> 0
A31: GRAFICO DE AVANCE POR PARTIDA
A32: PORCENTAJE POR PARTIDA | C32: =+AVERAGE(C7:C30) -> 0.15 | D32: =+AVERAGE(D7:D30) -> 0.083333333 | E32: =+AVERAGE(E7:E30) -> 0.083333333 | F32: =+AVERAGE(F7:F30) -> 0.36666667 | G32: =+AVERAGE(G7:G30) -> 0.16666667 | H32: =+AVERAGE(H7:H30) -> 0.34583333 | I32: =+AVERAGE(I7:I30) -> 0.083333333 | J32: =+AVERAGE(J7:J30) -> 0.083333333 | ... Q32: =+AVERAGE(Q7:Q30) -> 0.125
A33: AVANCE GENERAL PISO N° 1 | C33: =+AVERAGE(C32:Q32) -> 0.11861111
A34: PISO N° 2 A | B34: Depto 202 | C34: 0 | D34: 0 | E34: 0 | F34: 0 | G34: 0 | H34: 0 | I34: 0 | J34: 0 | K34: 0 | L34: 0 | M34: 0 | N34: 0 | O34: 0 | P34: 0 | Q34: 0 | R34: =+AVERAGE(C34:Q34) -> 0
B35: Depto.203 | C35: 0 | D35: 0 | E35: 0 | F35: 0 | G35: 0 | H35: 0 | I35: 0 | J35: 0 | K35: 0 | L35: 0 | M35: 0 | N35: 0 | O35: 0 | P35: 0 | Q35: 0 | R35: =+AVERAGE(C35:Q35) -> 0
B36: Depto.204 | C36: 0 | D36: 0 | E36: 0 | F36: 0 | G36: 0 | H36: 0 | I36: 0 | J36: 0 | K36: 0 | L36: 0 | M36: 0 | N36: 0 | O36: 0 | P36: 0 | Q36: 0 | R36: =+AVERAGE(C36:Q36) -> 0
B37: Depto.205 | C37: 0 | D37: 0 | E37: 0 | F37: 0 | G37: 0 | H37: 0 | I37: 0 | J37: 0 | K37: 0 | L37: 0 | M37: 0 | N37: 0 | O37: 0 | P37: 0 | Q37: 0 | R37: =+AVERAGE(C37:Q37) -> 0
B38: Depto.206 | C38: 0 | D38: 0 | E38: 0 | F38: 0 | G38: 0 | H38: 0 | I38: 0 | J38: 0 | K38: 0 | L38: 0 | M38: 0 | N38: 0 | O38: 0 | P38: 0 | Q38: 0 | R38: =+AVERAGE(C38:Q38) -> 0
B39: Depto.207 | C39: 0 | D39: 0 | E39: 0 | F39: 0 | G39: 0 | H39: 0 | I39: 0 | J39: 0 | K39: 0 | L39: 0 | M39: 0 | N39: 0 | O39: 0 | P39: 0 | Q39: 0 | R39: =+AVERAGE(C39:Q39) -> 0
B40: Depto.208 | C40: 0 | D40: 0 | E40: 0 | F40: 0 | G40: 0 | H40: 0 | I40: 0 | J40: 0 | K40: 0 | L40: 0 | M40: 0 | N40: 0 | O40: 0 | P40: 0 | Q40: 0 | R40: =+AVERAGE(C40:Q40) -> 0
B41: Depto.209 | C41: 0 | D41: 0 | E41: 0 | F41: 0 | G41: 0 | H41: 0 | I41: 0 | J41: 0 | K41: 0 | L41: 0 | M41: 0 | N41: 0 | O41: 0 | P41: 0 | Q41: 0 | R41: =+AVERAGE(C41:Q41) -> 0
B42: Depto.210 | C42: 0 | D42: 0 | E42: 0 | F42: 0 | G42: 0 | H42: 0 | I42: 0 | J42: 0 | K42: 0 | L42: 0 | M42: 0 | N42: 0 | O42: 0 | P42: 0 | Q42: 0 | R42: =+AVERAGE(C42:Q42) -> 0
B43: Depto.211 | C43: 0 | D43: 0 | E43: 0 | F43: 0 | G43: 0 | H43: 0 | I43: 0 | J43: 0 | K43: 0 | L43: 0 | M43: 0 | N43: 0 | O43: 0 | P43: 0 | Q43: 0 | R43: =+AVERAGE(C43:Q43) -> 0
B44: Depto.212 | C44: 0 | D44: 0 | E44: 0 | F44: 0 | G44: 0 | H44: 0 | I44: 0 | J44: 0 | K44: 0 | L44: 0 | M44: 0 | N44: 0 | O44: 0 | P44: 0 | Q44: 0 | R44: =+AVERAGE(C44:Q44) -> 0
B45: Depto.213 | C45: 0 | D45: 0 | E45: 0 | F45: 0 | G45: 0 | H45: 0 | I45: 0 | J45: 0 | K45: 0 | L45: 0 | M45: 0 | N45: 0 | O45: 0 | P45: 0 | Q45: 0 | R45: =+AVERAGE(C45:Q45) -> 0
B46: Depto.214 | C46: 0 | D46: 0 | E46: 0 | F46: 0 | G46: 0 | H46: 0 | I46: 0 | J46: 0 | K46: 0 | L46: 0 | M46: 0 | N46: 0 | O46: 0 | P46: 0 | Q46: 0 | R46: =+AVERAGE(C46:Q46) -> 0
... B55: Depto.223 | C55: 0 | D55: 0 | E55: 0 | F55: 0 | G55: 0 | H55: 0 | I55: 0 | J55: 0 | K55: 0 | L55: 0 | M55: 0 | N55: 0 | O55: 0 | P55: 0 | Q55: 0 | R55: =+AVERAGE(C55:Q55) -> 0
A56: PISO N° 2 B | B56: Depto.201 | C56: 0 | D56: 0 | E56: 0 | F56: 0 | G56: 0 | H56: 0 | I56: 0 | J56: 0 | K56: 0 | L56: 0 | M56: 0 | N56: 0 | O56: 0 | P56: 0 | Q56: 0 | R56: =+AVERAGE(C56:Q56) -> 0
B57: Depto.202 | C57: 0 | D57: 0 | E57: 0 | F57: 0 | G57: 0 | H57: 0 | I57: 0 | J57: 0 | K57: 0 | L57: 0 | M57: 0 | N57: 0 | O57: 0 | P57: 0 | Q57: 0 | R57: =+AVERAGE(C57:Q57) -> 0
B58: Depto.203 | C58: 0 | D58: 0 | E58: 0 | F58: 0 | G58: 0 | H58: 0 | I58: 0 | J58: 0 | K58: 0 | L58: 0 | M58: 0 | N58: 0 | O58: 0 | P58: 0 | Q58: 0 | R58: =+AVERAGE(C58:Q58) -> 0
B59: Depto.204 | C59: 0 | D59: 0 | E59: 0 | F59: 0 | G59: 0 | H59: 0 | I59: 0 | J59: 0 | K59: 0 | L59: 0 | M59: 0 | N59: 0 | O59: 0 | P59: 0 | Q59: 0 | R59: =+AVERAGE(C59:Q59) -> 0
...

Sheet AVANCE SEMANAL 1
G2: AVANCE SEMANAL POR PARTIDAS LYON
D4: MAYO | E4: MAYO | F4: JUNIO | G4: JUNIO | H4: JUNIO | I4: JULIO | J4: JULIO | K4: JULIO | L4: AGOSTO
C6: Partidas | D6: PISO | E6: PISO | F6: PISO | G6: PISO | H6: PISO | I6: PISO | J6: PISO | K6: PISO | L6: PISO | M6: PISO | N6: PISO | O6: PISO | P6: % Avance Real | Q6: % Avance Programado | W6: Insidencia en Dias | X6: METAS
D7: 1 | E7: 2 | F7: 3 | G7: 4 | H7: 5 | I7: 6 | J7: 7 | K7: 8 | L7: 9 | M7: 10 | N7: 11 | O7: 12
Q8: NOVIEMBRE | R8: DICIEMBRE | S8: ENERO | T8: FEBRERO | U8: MARZO
C9: =0%/100 -> 0 | D9: =8.33333333333333%*D7 -> 0.083333333 | E9: =8.33333333333333%*E7 -> 0.16666667 | F9: =8.33333333333333%*F7 -> 0.25 | G9: =8.33333333333333%*G7 -> 0.33333333 | H9: =8.33333333333333%*H7 -> 0.41666667 | I9: =8.33333333333333%*I7 -> 0.5 | J9: =8.33333333333333%*J7 -> 0.58333333 | K9: =8.33333333333333%*K7 -> 0.66666667 | ... O9: =8.33333333333333%*O7 -> 1 | Q9: =+H9 -> 0.41666667 | R9: =+J9 -> 0.58333333 | S9: =+L9 -> 0.75 | T9: =+N9 -> 0.91666667 | U9: =+O9 -> 1
B10: FASE 1 | C10: Recepción Obra Gruesa | D10: =+_xlfn.XLOOKUP($C10,'FASE 1 '!$C$421:$V$421,'FASE 1 '!$C$423:$V$423) -> #N/A | E10: =+_xlfn.XLOOKUP($C10,'FASE 1 '!$C$421:$V$421,'FASE 1 '!$C$424:$V$424) -> #N/A | F10: =+_xlfn.XLOOKUP($C10,'FASE 1 '!$C$421:$V$421,'FASE 1 '!$C$425:$V$425) -> #N/A | G10: =+_xlfn.XLOOKUP($C10,'FASE 1 '!$C$421:$V$421,'FASE 1 '!$C$426:$V$426) -> #N/A | H10: =+_xlfn.XLOOKUP($C10,'FASE 1 '!$C$421:$V$421,'FASE 1 '!$C$427:$V$427) -> #N/A | I10: =+_xlfn.XLOOKUP($C10,'FASE 1 '!$C$421:$V$421,'FASE 1 '!$C$428:$V$428) -> #N/A | J10: =+_xlfn.XLOOKUP($C10,'FASE 1 '!$C$421:$V$421,'FASE 1 '!$C$429:$V$429) -> #N/A | K10: =+_xlfn.XLOOKUP($C10,'FASE 1 '!$C$421:$V$421,'FASE 1 '!$C$430:$V$430) -> #N/A | L10: =+_xlfn.XLOOKUP($C10,'FASE 1 '!$C$421:$V$421,'FASE 1 '!$C$431:$V$431) -> #N/A | M10: =+_xlfn.XLOOKUP($C10,'FASE 1 '!$C$421:$V$421,'FASE 1 '!#REF!) -> #REF! | N10: =+_xlfn.XLOOKUP($C10,'FASE 1 '!$C$421:$V$421,'FASE 1 '!#REF!) -> #REF! | O10: =+_xlfn.XLOOKUP($C10,'FASE 1 '!$C$421:$V$421,'FASE 1 '!#REF!) -> #REF! | P10: =+AVERAGE(D10:O10) -> #N/A | Q10: =P10 -> #N/A
C11: Cangueo y desbaste de pisos | D11: =+_xlfn.XLOOKUP($C11,'FASE 1 '!$C$421:$V$421,'FASE 1 '!$C$423:$V$423) -> #N/A | E11: =+_xlfn.XLOOKUP($C11,'FASE 1 '!$C$421:$V$421,'FASE 1 '!$C$424:$V$424) -> #N/A | F11: =+_xlfn.XLOOKUP($C11,'FASE 1 '!$C$421:$V$421,'FASE 1 '!$C$425:$V$425) -> #N/A | G11: =+_xlfn.XLOOKUP($C11,'FASE 1 '!$C$421:$V$421,'FASE 1 '!$C$426:$V$426) -> #N/A | H11: =+_xlfn.XLOOKUP($C11,'FASE 1 '!$C$421:$V$421,'FASE 1 '!$C$427:$V$427) -> #N/A | I11: =+_xlfn.XLOOKUP($C11,'FASE 1 '!$C$421:$V$421,'FASE 1 '!$C$428:$V$428) -> #N/A | J11: =+_xlfn.XLOOKUP($C11,'FASE 1 '!$C$421:$V$421,'FASE 1 '!$C$429:$V$429) -> #N/A | K11: =+_xlfn.XLOOKUP($C11,'FASE 1 '!$C$421:$V$421,'FASE 1 '!$C$430:$V$430) -> #N/A | L11: =+_xlfn.XLOOKUP($C11,'FASE 1 '!$C$421:$V$421,'FASE 1 '!$C$431:$V$431) -> #N/A | M11: =+_xlfn.XLOOKUP($C11,'FASE 1 '!$C$421:$V$421,'FASE 1 '!#REF!) -> #REF! | N11: =+_xlfn.XLOOKUP($C11,'FASE 1 '!$C$421:$V$421,'FASE 1 '!#REF!) -> #REF! | O11: =+_xlfn.XLOOKUP($C11,'FASE 1 '!$C$421:$V$421,'FASE 1 '!#REF!) -> #REF! | P11: =+AVERAGE(D11:O11) -> #N/A | Q11: =P11 -> #N/A
C12: Retiro camisas / Tapado Pasadas | D12: =+_xlfn.XLOOKUP($C12,'FASE 1 '!$C$421:$V$421,'FASE 1 '!$C$423:$V$423) -> 0.58333333 | E12: =+_xlfn.XLOOKUP($C12,'FASE 1 '!$C$421:$V$421,'FASE 1 '!$C$424:$V$424) -> 0.97674419 | F12: =+_xlfn.XLOOKUP($C12,'FASE 1 '!$C$421:$V$421,'FASE 1 '!$C$425:$V$425) -> 0.47727273 | G12: =+_xlfn.XLOOKUP($C12,'FASE 1 '!$C$421:$V$421,'FASE 1 '!$C$426:$V$426) -> 0 | H12: =+_xlfn.XLOOKUP($C12,'FASE 1 '!$C$421:$V$421,'FASE 1 '!$C$427:$V$427) -> 0 | I12: =+_xlfn.XLOOKUP($C12,'FASE 1 '!$C$421:$V$421,'FASE 1 '!$C$428:$V$428) -> 0 | J12: =+_xlfn.XLOOKUP($C12,'FASE 1 '!$C$421:$V$421,'FASE 1 '!$C$429:$V$429) -> 0 | K12: =+_xlfn.XLOOKUP($C12,'FASE 1 '!$C$421:$V$421,'FASE 1 '!$C$430:$V$430) -> 0 | L12: =+_xlfn.XLOOKUP($C12,'FASE 1 '!$C$421:$V$421,'FASE 1 '!$C$431:$V$431) -> 0 | M12: =+_xlfn.XLOOKUP($C12,'FASE 1 '!$C$421:$V$421,'FASE 1 '!#REF!) -> #REF! | N12: =+_xlfn.XLOOKUP($C12,'FASE 1 '!$C$421:$V$421,'FASE 1 '!#REF!) -> #REF! | O12: =+_xlfn.XLOOKUP($C12,'FASE 1 '!$C$421:$V$421,'FASE 1 '!#REF!) -> #REF! | P12: =+AVERAGE(D12:O12) -> #REF! | Q12: =P12 -> #REF!
C13: Pulido, descarachado y preparacion de muros | D13: =+_xlfn.XLOOKUP($C13,'FASE 1 '!$C$421:$V$421,'FASE 1 '!$C$423:$V$423) -> 0.58333333 | E13: =+_xlfn.XLOOKUP($C13,'FASE 1 '!$C$421:$V$421,'FASE 1 '!$C$424:$V$424) -> 0.95348837 | F13: =+_xlfn.XLOOKUP($C13,'FASE 1 '!$C$421:$V$421,'FASE 1 '!$C$425:$V$425) -> 0.18181818 | G13: =+_xlfn.XLOOKUP($C13,'FASE 1 '!$C$421:$V$421,'FASE 1 '!$C$426:$V$426) -> 0 | H13: =+_xlfn.XLOOKUP($C13,'FASE 1 '!$C$421:$V$421,'FASE 1 '!$C$427:$V$427) -> 0 | I13: =+_xlfn.XLOOKUP($C13,'FASE 1 '!$C$421:$V$421,'FASE 1 '!$C$428:$V$428) -> 0 | J13: =+_xlfn.XLOOKUP($C13,'FASE 1 '!$C$421:$V$421,'FASE 1 '!$C$429:$V$429) -> 0 | K13: =+_xlfn.XLOOKUP($C13,'FASE 1 '!$C$421:$V$421,'FASE 1 '!$C$430:$V$430) -> 0 | L13: =+_xlfn.XLOOKUP($C13,'FASE 1 '!$C$421:$V$421,'FASE 1 '!$C$431:$V$431) -> 0 | M13: =+_xlfn.XLOOKUP($C13,'FASE 1 '!$C$421:$V$421,'FASE 1 '!#REF!) -> #REF! | N13: =+_xlfn.XLOOKUP($C13,'FASE 1 '!$C$421:$V$421,'FASE 1 '!#REF!) -> #REF! | O13: =+_xlfn.XLOOKUP($C13,'FASE 1 '!$C$421:$V$421,'FASE 1 '!#REF!) -> #REF! | P13: =+AVERAGE(D13:O13) -> #REF! | Q13: =P13 -> #REF!
C14: Trazado tabique/Yeso/auxiliares vent. Y puertas | D14: =+_xlfn.XLOOKUP($C14,'FASE 1 '!$C$421:$V$421,'FASE 1 '!$C$423:$V$423) -> 0.58333333 | E14: =+_xlfn.XLOOKUP($C14,'FASE 1 '!$C$421:$V$421,'FASE 1 '!$C$424:$V$424) -> 0.26511628 | F14: =+_xlfn.XLOOKUP($C14,'FASE 1 '!$C$421:$V$421,'FASE 1 '!$C$425:$V$425) -> 0.18181818 | G14: =+_xlfn.XLOOKUP($C14,'FASE 1 '!$C$421:$V$421,'FASE 1 '!$C$426:$V$426) -> 0 | H14: =+_xlfn.XLOOKUP($C14,'FASE 1 '!$C$421:$V$421,'FASE 1 '!$C$427:$V$427) -> 0 | I14: =+_xlfn.XLOOKUP($C14,'FASE 1 '!$C$421:$V$421,'FASE 1 '!$C$428:$V$428) -> 0 | J14: =+_xlfn.XLOOKUP($C14,'FASE 1 '!$C$421:$V$421,'FASE 1 '!$C$429:$V$429) -> 0 | K14: =+_xlfn.XLOOKUP($C14,'FASE 1 '!$C$421:$V$421,'FASE 1 '!$C$430:$V$430) -> 0 | L14: =+_xlfn.XLOOKUP($C14,'FASE 1 '!$C$421:$V$421,'FASE 1 '!$C$431:$V$431) -> 0 | M14: =+_xlfn.XLOOKUP($C14,'FASE 1 '!$C$421:$V$421,'FASE 1 '!#REF!) -> #REF! | N14: =+_xlfn.XLOOKUP($C14,'FASE 1 '!$C$421:$V$421,'FASE 1 '!#REF!) -> #REF! | O14: =+_xlfn.XLOOKUP($C14,'FASE 1 '!$C$421:$V$421,'FASE 1 '!#REF!) -> #REF! | P14: =+AVERAGE(D14:O14) -> #REF! | Q14: =P14 -> #REF!
C15: Chequeo Rasgos Puerta Acceso | D15: =+_xlfn.XLOOKUP($C15,'FASE 1 '!$C$421:$V$421,'FASE 1 '!$C$423:$V$423) -> 0.38333333 | E15: =+_xlfn.XLOOKUP($C15,'FASE 1 '!$C$421:$V$421,'FASE 1 '!$C$424:$V$424) -> 0.29767442 | F15: =+_xlfn.XLOOKUP($C15,'FASE 1 '!$C$421:$V$421,'FASE 1 '!$C$425:$V$425) -> 0.18181818 | G15: =+_xlfn.XLOOKUP($C15,'FASE 1 '!$C$421:$V$421,'FASE 1 '!$C$426:$V$426) -> 0 | H15: =+_xlfn.XLOOKUP($C15,'FASE 1 '!$C$421:$V$421,'FASE 1 '!$C$427:$V$427) -> 0 | I15: =+_xlfn.XLOOKUP($C15,'FASE 1 '!$C$421:$V$421,'FASE 1 '!$C$428:$V$428) -> 0 | J15: =+_xlfn.XLOOKUP($C15,'FASE 1 '!$C$421:$V$421,'FASE 1 '!$C$429:$V$429) -> 0 | K15: =+_xlfn.XLOOKUP($C15,'FASE 1 '!$C$421:$V$421,'FASE 1 '!$C$430:$V$430) -> 0 | L15: =+_xlfn.XLOOKUP($C15,'FASE 1 '!$C$421:$V$421,'FASE 1 '!$C$431:$V$431) -> 0 | M15: =+_xlfn.XLOOKUP($C15,'FASE 1 '!$C$421:$V$421,'FASE 1 '!#REF!) -> #REF! | N15: =+_xlfn.XLOOKUP($C15,'FASE 1 '!$C$421:$V$421,'FASE 1 '!#REF!) -> #REF! | O15: =+_xlfn.XLOOKUP($C15,'FASE 1 '!$C$421:$V$421,'FASE 1 '!#REF!) -> #REF! | P15: =+AVERAGE(D15:O15) -> #REF! | Q15: =P15 -> #REF!
C16: Grada Buque (9cm) | D16: =+_xlfn.XLOOKUP($C16,'FASE 1 '!$C$421:$V$421,'FASE 1 '!$C$423:$V$423) -> 0.58333333 | E16: =+_xlfn.XLOOKUP($C16,'FASE 1 '!$C$421:$V$421,'FASE 1 '!$C$424:$V$424) -> 0.46511628 | F16: =+_xlfn.XLOOKUP($C16,'FASE 1 '!$C$421:$V$421,'FASE 1 '!$C$425:$V$425) -> 0 | G16: =+_xlfn.XLOOKUP($C16,'FASE 1 '!$C$421:$V$421,'FASE 1 '!$C$426:$V$426) -> 0 | H16: =+_xlfn.XLOOKUP($C16,'FASE 1 '!$C$421:$V$421,'FASE 1 '!$C$427:$V$427) -> 0 | I16: =+_xlfn.XLOOKUP($C16,'FASE 1 '!$C$421:$V$421,'FASE 1 '!$C$428:$V$428) -> 0 | J16: =+_xlfn.XLOOKUP($C16,'FASE 1 '!$C$421:$V$421,'FASE 1 '!$C$429:$V$429) -> 0 | K16: =+_xlfn.XLOOKUP($C16,'FASE 1 '!$C$421:$V$421,'FASE 1 '!$C$430:$V$430) -> 0 | L16: =+_xlfn.XLOOKUP($C16,'FASE 1 '!$C$421:$V$421,'FASE 1 '!$C$431:$V$431) -> 0 | M16: =+_xlfn.XLOOKUP($C16,'FASE 1 '!$C$421:$V$421,'FASE 1 '!#REF!) -> #REF! | N16: =+_xlfn.XLOOKUP($C16,'FASE 1 '!$C$421:$V$421,'FASE 1 '!#REF!) -> #REF! | O16: =+_xlfn.XLOOKUP($C16,'FASE 1 '!$C$421:$V$421,'FASE 1 '!#REF!) -> #REF! | P16: =+AVERAGE(D16:O16) -> #REF! | Q16: =P16 -> #REF!
C17: Rasgo ventana - terrazas | D17: =+_xlfn.XLOOKUP($C17,'FASE 1 '!$C$421:$V$421,'FASE 1 '!$C$423:$V$423) -> 0.575 | E17: =+_xlfn.XLOOKUP($C17,'FASE 1 '!$C$421:$V$421,'FASE 1 '!$C$424:$V$424) -> 0.19883721 | F17: =+_xlfn.XLOOKUP($C17,'FASE 1 '!$C$421:$V$421,'FASE 1 '!$C$425:$V$425) -> 0 | G17: =+_xlfn.XLOOKUP($C17,'FASE 1 '!$C$421:$V$421,'FASE 1 '!$C$426:$V$426) -> 0 | H17: =+_xlfn.XLOOKUP($C17,'FASE 1 '!$C$421:$V$421,'FASE 1 '!$C$427:$V$427) -> 0 | I17: =+_xlfn.XLOOKUP($C17,'FASE 1 '!$C$421:$V$421,'FASE 1 '!$C$428:$V$428) -> 0 | J17: =+_xlfn.XLOOKUP($C17,'FASE 1 '!$C$421:$V$421,'FASE 1 '!$C$429:$V$429) -> 0 | K17: =+_xlfn.XLOOKUP($C17,'FASE 1 '!$C$421:$V$421,'FASE 1 '!$C$430:$V$430) -> 0 | L17: =+_xlfn.XLOOKUP($C17,'FASE 1 '!$C$421:$V$421,'FASE 1 '!$C$431:$V$431) -> 0 | M17: =+_xlfn.XLOOKUP($C17,'FASE 1 '!$C$421:$V$421,'FASE 1 '!#REF!) -> #REF! | N17: =+_xlfn.XLOOKUP($C17,'FASE 1 '!$C$421:$V$421,'FASE 1 '!#REF!) -> #REF! | O17: =+_xlfn.XLOOKUP($C17,'FASE 1 '!$C$421:$V$421,'FASE 1 '!#REF!) -> #REF! | P17: =+AVERAGE(D17:O17) -> #REF! | Q17: =P17 -> #REF!
C18: Despeje caja electricas | D18: =+_xlfn.XLOOKUP($C18,'FASE 1 '!$C$421:$V$421,'FASE 1 '!$C$423:$V$423) -> 0.52083333 | E18: =+_xlfn.XLOOKUP($C18,'FASE 1 '!$C$421:$V$421,'FASE 1 '!$C$424:$V$424) -> 0.48837209 | F18: =+_xlfn.XLOOKUP($C18,'FASE 1 '!$C$421:$V$421,'FASE 1 '!$C$425:$V$425) -> 0.12272727 | G18: =+_xlfn.XLOOKUP($C18,'FASE 1 '!$C$421:$V$421,'FASE 1 '!$C$426:$V$426) -> 0 | H18: =+_xlfn.XLOOKUP($C18,'FASE 1 '!$C$421:$V$421,'FASE 1 '!$C$427:$V$427) -> 0 | I18: =+_xlfn.XLOOKUP($C18,'FASE 1 '!$C$421:$V$421,'FASE 1 '!$C$428:$V$428) -> 0 | J18: =+_xlfn.XLOOKUP($C18,'FASE 1 '!$C$421:$V$421,'FASE 1 '!$C$429:$V$429) -> 0 | K18: =+_xlfn.XLOOKUP($C18,'FASE 1 '!$C$421:$V$421,'FASE 1 '!$C$430:$V$430) -> 0 | L18: =+_xlfn.XLOOKUP($C18,'FASE 1 '!$C$421:$V$421,'FASE 1 '!$C$431:$V$431) -> 0 | M18: =+_xlfn.XLOOKUP($C18,'FASE 1 '!$C$421:$V$421,'FASE 1 '!#REF!) -> #REF! | N18: =+_xlfn.XLOOKUP($C18,'FASE 1 '!$C$421:$V$421,'FASE 1 '!#REF!) -> #REF! | O18: =+_xlfn.XLOOKUP($C18,'FASE 1 '!$C$421:$V$421,'FASE 1 '!#REF!) -> #REF! | P18: =+AVERAGE(D18:O18) -> #REF! | Q18: =P18 -> #REF!
C19: Yeso Muro | D19: =+_xlfn.XLOOKUP($C19,'FASE 1 '!$C$421:$V$421,'FASE 1 '!$C$423:$V$423) -> 0.58333333 | E19: =+_xlfn.XLOOKUP($C19,'FASE 1 '!$C$421:$V$421,'FASE 1 '!$C$424:$V$424) -> 0.45348837 | F19: =+_xlfn.XLOOKUP($C19,'FASE 1 '!$C$421:$V$421,'FASE 1 '!$C$425:$V$425) -> 0.18181818 | G19: =+_xlfn.XLOOKUP($C19,'FASE 1 '!$C$421:$V$421,'FASE 1 '!$C$426:$V$426) -> 0 | H19: =+_xlfn.XLOOKUP($C19,'FASE 1 '!$C$421:$V$421,'FASE 1 '!$C$427:$V$427) -> 0 | I19: =+_xlfn.XLOOKUP($C19,'FASE 1 '!$C$421:$V$421,'FASE 1 '!$C$428:$V$428) -> 0 | J19: =+_xlfn.XLOOKUP($C19,'FASE 1 '!$C$421:$V$421,'FASE 1 '!$C$429:$V$429) -> 0 | K19: =+_xlfn.XLOOKUP($C19,'FASE 1 '!$C$421:$V$421,'FASE 1 '!$C$430:$V$430) -> 0 | L19: =+_xlfn.XLOOKUP($C19,'FASE 1 '!$C$421:$V$421,'FASE 1 '!$C$431:$V$431) -> 0 | M19: =+_xlfn.XLOOKUP($C19,'FASE 1 '!$C$421:$V$421,'FASE 1 '!#REF!) -> #REF! | N19: =+_xlfn.XLOOKUP($C19,'FASE 1 '!$C$421:$V$421,'FASE 1 '!#REF!) -> #REF! | O19: =+_xlfn.XLOOKUP($C19,'FASE 1 '!$C$421:$V$421,'FASE 1 '!#REF!) -> #REF! | P19: =+AVERAGE(D19:O19) -> #REF! | Q19: =P19 -> #REF!
C20: Yeso Cielo | D20: =+_xlfn.XLOOKUP($C20,'FASE 1 '!$C$421:$V$421,'FASE 1 '!$C$423:$V$423) -> 0.58333333 | E20: =+_xlfn.XLOOKUP($C20,'FASE 1 '!$C$421:$V$421,'FASE 1 '!$C$424:$V$424) -> 0.18604651 | F20: =+_xlfn.XLOOKUP($C20,'FASE 1 '!$C$421:$V$421,'FASE 1 '!$C$425:$V$425) -> 0 | G20: =+_xlfn.XLOOKUP($C20,'FASE 1 '!$C$421:$V$421,'FASE 1 '!$C$426:$V$426) -> 0 | H20: =+_xlfn.XLOOKUP($C20,'FASE 1 '!$C$421:$V$421,'FASE 1 '!$C$427:$V$427) -> 0 | I20: =+_xlfn.XLOOKUP($C20,'FASE 1 '!$C$421:$V$421,'FASE 1 '!$C$428:$V$428) -> 0 | J20: =+_xlfn.XLOOKUP($C20,'FASE 1 '!$C$421:$V$421,'FASE 1 '!$C$429:$V$429) -> 0 | K20: =+_xlfn.XLOOKUP($C20,'FASE 1 '!$C$421:$V$421,'FASE 1 '!$C$430:$V$430) -> 0 | L20: =+_xlfn.XLOOKUP($C20,'FASE 1 '!$C$421:$V$421,'FASE 1 '!$C$431:$V$431) -> 0 | M20: =+_xlfn.XLOOKUP($C20,'FASE 1 '!$C$421:$V$421,'FASE 1 '!#REF!) -> #REF! | N20: =+_xlfn.XLOOKUP($C20,'FASE 1 '!$C$421:$V$421,'FASE 1 '!#REF!) -> #REF! | O20: =+_xlfn.XLOOKUP($C20,'FASE 1 '!$C$421:$V$421,'FASE 1 '!#REF!) -> #REF! | P20: =+AVERAGE(D20:O20) -> #REF! | Q20: =P20 -> #REF!
C21: Sanitario vertical y ramal | D21: =+_xlfn.XLOOKUP($C21,'FASE 1 '!$C$421:$V$421,'FASE 1 '!$C$423:$V$423) -> 0.31666667 | E21: =+_xlfn.XLOOKUP($C21,'FASE 1 '!$C$421:$V$421,'FASE 1 '!$C$424:$V$424) -> 0 | F21: =+_xlfn.XLOOKUP($C21,'FASE 1 '!$C$421:$V$421,'FASE 1 '!$C$425:$V$425) -> 0 | G21: =+_xlfn.XLOOKUP($C21,'FASE 1 '!$C$421:$V$421,'FASE 1 '!$C$426:$V$426) -> 0 | H21: =+_xlfn.XLOOKUP($C21,'FASE 1 '!$C$421:$V$421,'FASE 1 '!$C$427:$V$427) -> 0 | I21: =+_xlfn.XLOOKUP($C21,'FASE 1 '!$C$421:$V$421,'FASE 1 '!$C$428:$V$428) -> 0 | J21: =+_xlfn.XLOOKUP($C21,'FASE 1 '!$C$421:$V$421,'FASE 1 '!$C$429:$V$429) -> 0 | K21: =+_xlfn.XLOOKUP($C21,'FASE 1 '!$C$421:$V$421,'FASE 1 '!$C$430:$V$430) -> 0 | L21: =+_xlfn.XLOOKUP($C21,'FASE 1 '!$C$421:$V$421,'FASE 1 '!$C$431:$V$431) -> 0 | M21: =+_xlfn.XLOOKUP($C21,'FASE 1 '!$C$421:$V$421,'FASE 1 '!#REF!) -> #REF! | N21: =+_xlfn.XLOOKUP($C21,'FASE 1 '!$C$421:$V$421,'FASE 1 '!#REF!) -> #REF! | O21: =+_xlfn.XLOOKUP($C21,'FASE 1 '!$C$421:$V$421,'FASE 1 '!#REF!) -> #REF! | P21: =+AVERAGE(D21:O21) -> #REF! | Q21: =P21 -> #REF!
C22: Instalación Lana Mineral | D22: =+_xlfn.XLOOKUP($C22,'FASE 1 '!$C$421:$V$421,'FASE 1 '!$C$423:$V$423) -> #N/A | E22: =+_xlfn.XLOOKUP($C22,'FASE 1 '!$C$421:$V$421,'FASE 1 '!$C$424:$V$424) -> #N/A | F22: =+_xlfn.XLOOKUP($C22,'FASE 1 '!$C$421:$V$421,'FASE 1 '!$C$425:$V$425) -> #N/A | G22: =+_xlfn.XLOOKUP($C22,'FASE 1 '!$C$421:$V$421,'FASE 1 '!$C$426:$V$426) -> #N/A | H22: =+_xlfn.XLOOKUP($C22,'FASE 1 '!$C$421:$V$421,'FASE 1 '!$C$427:$V$427) -> #N/A | I22: =+_xlfn.XLOOKUP($C22,'FASE 1 '!$C$421:$V$421,'FASE 1 '!$C$428:$V$428) -> #N/A | J22: =+_xlfn.XLOOKUP($C22,'FASE 1 '!$C$421:$V$421,'FASE 1 '!$C$429:$V$429) -> #N/A | K22: =+_xlfn.XLOOKUP($C22,'FASE 1 '!$C$421:$V$421,'FASE 1 '!$C$430:$V$430) -> #N/A | L22: =+_xlfn.XLOOKUP($C22,'FASE 1 '!$C$421:$V$421,'FASE 1 '!$C$431:$V$431) -> #N/A | M22: =+_xlfn.XLOOKUP($C22,'FASE 1 '!$C$421:$V$421,'FASE 1 '!#REF!) -> #REF! | N22: =+_xlfn.XLOOKUP($C22,'FASE 1 '!$C$421:$V$421,'FASE 1 '!#REF!) -> #REF! | O22: =+_xlfn.XLOOKUP($C22,'FASE 1 '!$C$421:$V$421,'FASE 1 '!#REF!) -> #REF! | P22: =+AVERAGE(D22:O22) -> #N/A | Q22: =P22 -> #N/A
... C26: Aislación Interior y Refuerzo Plasma | D26: =+_xlfn.XLOOKUP($C26,'FASE 1 '!$C$421:$V$421,'FASE 1 '!$C$423:$V$423) -> 0.45833333 | E26: =+_xlfn.XLOOKUP($C26,'FASE 1 '!$C$421:$V$421,'FASE 1 '!$C$424:$V$424) -> 0 | F26: =+_xlfn.XLOOKUP($C26,'FASE 1 '!$C$421:$V$421,'FASE 1 '!$C$425:$V$425) -> 0 | G26: =+_xlfn.XLOOKUP($C26,'FASE 1 '!$C$421:$V$421,'FASE 1 '!$C$426:$V$426) -> 0 | H26: =+_xlfn.XLOOKUP($C26,'FASE 1 '!$C$421:$V$421,'FASE 1 '!$C$427:$V$427) -> 0 | I26: =+_xlfn.XLOOKUP($C26,'FASE 1 '!$C$421:$V$421,'FASE 1 '!$C$428:$V$428) -> 0 | J26: =+_xlfn.XLOOKUP($C26,'FASE 1 '!$C$421:$V$421,'FASE 1 '!$C$429:$V$429) -> 0 | K26: =+_xlfn.XLOOKUP($C26,'FASE 1 '!$C$421:$V$421,'FASE 1 '!$C$430:$V$430) -> 0 | L26: =+_xlfn.XLOOKUP($C26,'FASE 1 '!$C$421:$V$421,'FASE 1 '!$C$431:$V$431) -> 0 | M26: =+_xlfn.XLOOKUP($C26,'FASE 1 '!$C$421:$V$421,'FASE 1 '!#REF!) -> #REF! | N26: =+_xlfn.XLOOKUP($C26,'FASE 1 '!$C$421:$V$421,'FASE 1 '!#REF!) -> #REF! | O26: =+_xlfn.XLOOKUP($C26,'FASE 1 '!$C$421:$V$421,'FASE 1 '!#REF!) -> #REF! | P26: =+AVERAGE(D26:O26) -> #REF! | Q26: =P26 -> #REF!
C27: Enlauchado | D27: =+_xlfn.XLOOKUP($C27,'FASE 1 '!$C$421:$V$421,'FASE 1 '!$C$423:$V$423) -> 0.083333333 | E27: =+_xlfn.XLOOKUP($C27,'FASE 1 '!$C$421:$V$421,'FASE 1 '!$C$423:$V$423) -> 0.083333333 | F27: =+_xlfn.XLOOKUP($C27,'FASE 1 '!$C$421:$V$421,'FASE 1 '!$C$423:$V$423) -> 0.083333333 | G27: =+_xlfn.XLOOKUP($C27,'FASE 1 '!$C$421:$V$421,'FASE 1 '!$C$423:$V$423) -> 0.083333333 | H27: =+_xlfn.XLOOKUP($C27,'FASE 1 '!$C$421:$V$421,'FASE 1 '!$C$423:$V$423) -> 0.083333333 | I27: =+_xlfn.XLOOKUP($C27,'FASE 1 '!$C$421:$V$421,'FASE 1 '!$C$423:$V$423) -> 0.083333333 | J27: =+_xlfn.XLOOKUP($C27,'FASE 1 '!$C$421:$V$421,'FASE 1 '!$C$423:$V$423) -> 0.083333333 | K27: =+_xlfn.XLOOKUP($C27,'FASE 1 '!$C$421:$V$421,'FASE 1 '!$C$423:$V$423) -> 0.083333333 | ... O27: =+_xlfn.XLOOKUP($C27,'FASE 1 '!$C$421:$V$421,'FASE 1 '!$C$423:$V$423) -> 0.083333333 | P27: =+AVERAGE(D27:O27) -> 0.083333333 | Q27: =P27 -> 0.083333333
C28: Instalaciones Interior Tabique | D28: =+_xlfn.XLOOKUP($C28,'FASE 1 '!$C$421:$V$421,'FASE 1 '!$C$423:$V$423) -> 0.45 | E28: =+_xlfn.XLOOKUP($C28,'FASE 1 '!$C$421:$V$421,'FASE 1 '!$C$424:$V$424) -> 0 | F28: =+_xlfn.XLOOKUP($C28,'FASE 1 '!$C$421:$V$421,'FASE 1 '!$C$425:$V$425) -> 0 | G28: =+_xlfn.XLOOKUP($C28,'FASE 1 '!$C$421:$V$421,'FASE 1 '!$C$426:$V$426) -> 0 | H28: =+_xlfn.XLOOKUP($C28,'FASE 1 '!$C$421:$V$421,'FASE 1 '!$C$427:$V$427) -> 0 | I28: =+_xlfn.XLOOKUP($C28,'FASE 1 '!$C$421:$V$421,'FASE 1 '!$C$428:$V$428) -> 0 | J28: =+_xlfn.XLOOKUP($C28,'FASE 1 '!$C$421:$V$421,'FASE 1 '!$C$429:$V$429) -> 0 | K28: =+_xlfn.XLOOKUP($C28,'FASE 1 '!$C$421:$V$421,'FASE 1 '!$C$430:$V$430) -> 0 | L28: =+_xlfn.XLOOKUP($C28,'FASE 1 '!$C$421:$V$421,'FASE 1 '!$C$431:$V$431) -> 0 | M28: =+_xlfn.XLOOKUP($C28,'FASE 1 '!$C$421:$V$421,'FASE 1 '!#REF!) -> #REF! | N28: =+_xlfn.XLOOKUP($C28,'FASE 1 '!$C$421:$V$421,'FASE 1 '!#REF!) -> #REF! | O28: =+_xlfn.XLOOKUP($C28,'FASE 1 '!$C$421:$V$421,'FASE 1 '!#REF!) -> #REF! | P28: =+AVERAGE(D28:O28) -> #REF! | Q28: =P28 -> #REF!
C29: Tabique 2° cara | D29: =+_xlfn.XLOOKUP($C29,'FASE 1 '!$C$421:$V$421,'FASE 1 '!$C$423:$V$423) -> 0.36041667 | E29: =+_xlfn.XLOOKUP($C29,'FASE 1 '!$C$421:$V$421,'FASE 1 '!$C$424:$V$424) -> 0 | F29: =+_xlfn.XLOOKUP($C29,'FASE 1 '!$C$421:$V$421,'FASE 1 '!$C$425:$V$425) -> 0 | G29: =+_xlfn.XLOOKUP($C29,'FASE 1 '!$C$421:$V$421,'FASE 1 '!$C$426:$V$426) -> 0 | H29: =+_xlfn.XLOOKUP($C29,'FASE 1 '!$C$421:$V$421,'FASE 1 '!$C$427:$V$427) -> 0 | I29: =+_xlfn.XLOOKUP($C29,'FASE 1 '!$C$421:$V$421,'FASE 1 '!$C$428:$V$428) -> 0 | J29: =+_xlfn.XLOOKUP($C29,'FASE 1 '!$C$421:$V$421,'FASE 1 '!$C$429:$V$429) -> 0 | K29: =+_xlfn.XLOOKUP($C29,'FASE 1 '!$C$421:$V$421,'FASE 1 '!$C$430:$V$430) -> 0 | L29: =+_xlfn.XLOOKUP($C29,'FASE 1 '!$C$421:$V$421,'FASE 1 '!$C$431:$V$431) -> 0 | M29: =+_xlfn.XLOOKUP($C29,'FASE 1 '!$C$421:$V$421,'FASE 1 '!#REF!) -> #REF! | N29: =+_xlfn.XLOOKUP($C29,'FASE 1 '!$C$421:$V$421,'FASE 1 '!#REF!) -> #REF! | O29: =+_xlfn.XLOOKUP($C29,'FASE 1 '!$C$421:$V$421,'FASE 1 '!#REF!) -> #REF! | P29: =+AVERAGE(D29:O29) -> #REF! | Q29: =P29 -> #REF!
C30: Shaft /Tabique | D30: =+_xlfn.XLOOKUP($C30,'FASE 1 '!$C$421:$V$421,'FASE 1 '!$C$423:$V$423) -> 0.13333333 | E30: =+_xlfn.XLOOKUP($C30,'FASE 1 '!$C$421:$V$421,'FASE 1 '!$C$424:$V$424) -> 0 | F30: =+_xlfn.XLOOKUP($C30,'FASE 1 '!$C$421:$V$421,'FASE 1 '!$C$425:$V$425) -> 0 | G30: =+_xlfn.XLOOKUP($C30,'FASE 1 '!$C$421:$V$421,'FASE 1 '!$C$426:$V$426) -> 0 | H30: =+_xlfn.XLOOKUP($C30,'FASE 1 '!$C$421:$V$421,'FASE 1 '!$C$427:$V$427) -> 0 | I30: =+_xlfn.XLOOKUP($C30,'FASE 1 '!$C$421:$V$421,'FASE 1 '!$C$428:$V$428) -> 0 | J30: =+_xlfn.XLOOKUP($C30,'FASE 1 '!$C$421:$V$421,'FASE 1 '!$C$429:$V$429) -> 0 | K30: =+_xlfn.XLOOKUP($C30,'FASE 1 '!$C$421:$V$421,'FASE 1 '!$C$430:$V$430) -> 0 | L30: =+_xlfn.XLOOKUP($C30,'FASE 1 '!$C$421:$V$421,'FASE 1 '!$C$431:$V$431) -> 0 | M30: =+_xlfn.XLOOKUP($C30,'FASE 1 '!$C$421:$V$421,'FASE 1 '!#REF!) -> #REF! | N30: =+_xlfn.XLOOKUP($C30,'FASE 1 '!$C$421:$V$421,'FASE 1 '!#REF!) -> #REF! | O30: =+_xlfn.XLOOKUP($C30,'FASE 1 '!$C$421:$V$421,'FASE 1 '!#REF!) -> #REF! | P30: =+AVERAGE(D30:O30) -> #REF! | Q30: =P30 -> #REF!
